package org.gte.gtecore.common.data.machines;

import org.gte.gtecore.GTECore;
import org.gte.gtecore.api.machine.multiblock.ElectricMultiblockMachine;
import org.gte.gtecore.api.machine.part.GTEPartAbility;
import org.gte.gtecore.api.pattern.GTEPredicates;
import org.gte.gtecore.client.renderer.machine.EyeOfHarmonyRenderer;
import org.gte.gtecore.client.renderer.machine.FluidRenderer;
import org.gte.gtecore.client.renderer.machine.GodforgeRenderer;
import org.gte.gtecore.client.renderer.machine.SpaceElevatorRenderer;
import org.gte.gtecore.common.block.FusionCasings;
import org.gte.gtecore.common.data.*;
import org.gte.gtecore.common.machine.multiblock.electric.*;
import org.gte.gtecore.common.machine.multiblock.electric.adventure.SlaughterhouseMachine;
import org.gte.gtecore.common.machine.multiblock.electric.assembly.AdvancedAssemblyLineMachine;
import org.gte.gtecore.common.machine.multiblock.electric.assembly.CircuitAssemblyLineMachine;
import org.gte.gtecore.common.machine.multiblock.electric.assembly.SuprachronalAssemblyLineMachine;
import org.gte.gtecore.common.machine.multiblock.electric.assembly.SuprachronalAssemblyLineModuleMachine;
import org.gte.gtecore.common.machine.multiblock.electric.bioengineering.IncubatorMachine;
import org.gte.gtecore.common.machine.multiblock.electric.nano.NanoForgeMachine;
import org.gte.gtecore.common.machine.multiblock.electric.processing.ColdIceFreezerMachine;
import org.gte.gtecore.common.machine.multiblock.electric.processing.ProcessingPlantMachine;
import org.gte.gtecore.common.machine.multiblock.electric.smelter.BlazeBlastFurnaceMachine;
import org.gte.gtecore.common.machine.multiblock.electric.smelter.DimensionallyTranscendentPlasmaForgeMachine;
import org.gte.gtecore.common.machine.multiblock.electric.space.SpaceElevatorMachine;
import org.gte.gtecore.common.machine.multiblock.electric.space.SpaceElevatorModuleMachine;
import org.gte.gtecore.common.machine.multiblock.electric.space.SpaceProbeSurfaceReceptionMachine;
import org.gte.gtecore.common.machine.multiblock.electric.voidseries.INFFluidDrillMachine;
import org.gte.gtecore.common.machine.multiblock.noenergy.HarmonyMachine;
import org.gte.gtecore.common.machine.multiblock.noenergy.HeatExchangerMachine;
import org.gte.gtecore.common.machine.multiblock.noenergy.NeutronActivatorMachine;
import org.gte.gtecore.common.machine.multiblock.noenergy.GodForgeMachine;
import org.gte.gtecore.utils.*;

import com.gregtechceu.gtceu.GTCEu;
import com.gregtechceu.gtceu.api.GTValues;
import com.gregtechceu.gtceu.api.data.chemical.ChemicalHelper;
import com.gregtechceu.gtceu.api.data.tag.TagPrefix;
import com.gregtechceu.gtceu.api.machine.MultiblockMachineDefinition;
import com.gregtechceu.gtceu.api.pattern.FactoryBlockPattern;
import com.gregtechceu.gtceu.api.pattern.MultiblockShapeInfo;
import com.gregtechceu.gtceu.api.pattern.Predicates;
import com.gregtechceu.gtceu.api.pattern.TraceabilityPredicate;
import com.gregtechceu.gtceu.api.pattern.util.RelativeDirection;
import com.gregtechceu.gtceu.client.renderer.machine.FusionReactorRenderer;
import com.gregtechceu.gtceu.common.data.*;
import com.gregtechceu.gtceu.common.machine.multiblock.electric.FusionReactorMachine;
import com.gregtechceu.gtceu.utils.FormattingUtil;

import net.minecraft.core.BlockPos;
import net.minecraft.core.Direction;
import net.minecraft.network.chat.Component;
import net.minecraft.server.MinecraftServer;
import net.minecraft.world.entity.Entity;
import net.minecraft.world.entity.item.ItemEntity;
import net.minecraft.world.entity.player.Player;
import net.minecraft.world.item.ItemStack;
import net.minecraft.world.level.Level;
import net.minecraft.world.level.block.Block;
import net.minecraft.world.level.block.Blocks;
import net.minecraft.world.level.block.DirectionalBlock;
import net.minecraft.world.phys.AABB;

import java.util.ArrayList;
import java.util.List;
import java.util.Locale;
import java.util.Objects;

import static com.gregtechceu.gtceu.api.machine.multiblock.PartAbility.*;
import static com.gregtechceu.gtceu.api.pattern.Predicates.*;
import static org.gte.gtecore.api.GTEValues.POWER_MODULE_TIER;
import static org.gte.gtecore.common.block.BlockMap.SEPMMAP;
import static org.gte.gtecore.utils.register.MachineRegisterUtils.multiblock;
import static org.gte.gtecore.utils.register.MachineRegisterUtils.registerTieredMultis;

public interface MultiBlockD {

    static void init() {}

    MultiblockMachineDefinition GREENHOUSE = multiblock("greenhouse", "温室", GreenhouseMachine::new)
            .nonYAxisRotation()
            .recipe(GTERecipeTypes.GREENHOUSE_RECIPES)
            .tooltipsText("Requires sunlight to operate", "需要阳光才能运行")
            .tooltipsText("If sunlight is insufficient, speed will slow down", "如太阳光照不足，速度就会减缓")
            .overclock()
            .block(GTBlocks.MACHINE_CASING_ULV)
            .pattern((definition) -> FactoryBlockPattern.start()
                    .aisle("0BBB0", "0BBB0", "0BBB0", "0BBB0", "0BBB0")
                    .aisle("BBBBB", "BdddB", "B###B", "B###B", "BGGGB")
                    .aisle("BBBBB", "BdddB", "B###B", "B###B", "BGGGB")
                    .aisle("BBBBB", "BdddB", "B###B", "B###B", "BGGGB")
                    .aisle("0BBB0", "0BEB0", "0BBB0", "0BBB0", "0BBB0")
                    .where('E', controller(blocks(definition.get())))
                    .where('G', blocks(GTBlocks.CASING_TEMPERED_GLASS.get()))
                    .where('B', blocks(GTBlocks.MACHINE_CASING_ULV.get())
                            .setMinGlobalLimited(40)
                            .or(autoAbilities(definition.getRecipeTypes()))
                            .or(abilities(MAINTENANCE).setExactLimit(1)))
                    .where('d', blocks(RegistriesUtils.getBlock("farmersdelight:rich_soil")))
                    .where('#', air())
                    .where('0', any())
                    .build())
            .workableCasingRenderer(GTCEu.id("block/casings/voltage/ulv/side"), GTCEu.id("block/multiblock/fusion_reactor"))
            .register();

    MultiblockMachineDefinition EYE_OF_HARMONY = multiblock("eye_of_harmony", "鸿蒙之眼", HarmonyMachine::new)
            .nonYAxisRotation()
            .recipe(GTERecipeTypes.COSMOS_SIMULATION_RECIPES)
            .tooltipsText("Creates a mini-universe and gathers resources inside", "创造一个微缩宇宙，并获取里面的资源")
            .tooltipsText("This multiBlock machine requires too much EU, unable to power with conventional means", "这台多方块机器需要太多EU，无法用常规手段供能")
            .tooltipsText("Directly supplied with EU from wireless EU network, specific values can be viewed in the GUI", "由无线EU网络直接供给EU，具体数值可在GUI内查看")
            .tooltipsText("Executes special overclocking mode, increasing speed by 2 times for every 16 times power increase, overclocking is adjusted by programmed circuits", "执行特殊超频模式，每提升16倍功率提升2倍速度，超频由编程电路调节")
            .tooltipsText("The circuit must be set up before starting, Circuit 1 does not execute overclocking, Circuits 2-4 execute 1, 2, and 3 times overclocking respectively", "在启动前设置好电路，电路1不执行超频，电路2 4 分别执行1、2、3次超频")
            .tooltipsText("Startup requires 1024B of cosmic matter and 1024KB of hydrogen and helium", "启动需1024B的宇宙素，与1024KB的氢和氦")
            .tooltipsText("Hydrogen and Helium are stored inside the machine and continue to consume before the machine is ready to work", "氢和氦存储在机器内部，在机器准备工作之前会持续消耗")
            .alwaysTryModifyRecipe(true)
            .block(GTBlocks.HIGH_POWER_CASING)
            .pattern(definition -> FactoryBlockPattern.start()
                    .aisle("                                 ", "                                 ", "                                 ", "                                 ", "                                 ", "                                 ", "                                 ", "                                 ", "                                 ", "                                 ", "                                 ", "                                 ", "               A A               ", "               A A               ", "               A A               ", "            AAAAAAAAA            ", "               A A               ", "            AAAAAAAAA            ", "               A A               ", "               A A               ", "               A A               ", "                                 ", "                                 ", "                                 ", "                                 ", "                                 ", "                                 ", "                                 ", "                                 ", "                                 ", "                                 ", "                                 ", "                                 ")
                    .aisle("                                 ", "                                 ", "                                 ", "                                 ", "                                 ", "                                 ", "                                 ", "                                 ", "                                 ", "               A A               ", "               A A               ", "               A A               ", "               A A               ", "              DDDDD              ", "             DDADADD             ", "         AAAADAADAADAAAA         ", "             DDDDDDD             ", "         AAAADAADAADAAAA         ", "             DDADADD             ", "              DDDDD              ", "               A A               ", "               A A               ", "               A A               ", "               A A               ", "                                 ", "                                 ", "                                 ", "                                 ", "                                 ", "                                 ", "                                 ", "                                 ", "                                 ")
                    .aisle("                                 ", "                                 ", "                                 ", "                                 ", "                                 ", "                                 ", "                                 ", "               A A               ", "               A A               ", "               A A               ", "                D                ", "                D                ", "             DDDDDDD             ", "            DD     DD            ", "            D  EEE  D            ", "       AAA  D EFFFE D  AAA       ", "          DDD EFFFE DDD          ", "       AAA  D EFFFE D  AAA       ", "            D  EEE  D            ", "            DD     DD            ", "             DDDDDDD             ", "                D                ", "                D                ", "               A A               ", "               A A               ", "               A A               ", "                                 ", "                                 ", "                                 ", "                                 ", "                                 ", "                                 ", "                                 ")
                    .aisle("                                 ", "                                 ", "                                 ", "                                 ", "                                 ", "                                 ", "               A A               ", "               A A               ", "                D                ", "                D                ", "                                 ", "                                 ", "                                 ", "                                 ", "                                 ", "      AA                 AA      ", "        DD             DD        ", "      AA                 AA      ", "                                 ", "                                 ", "                                 ", "                                 ", "                                 ", "                D                ", "                D                ", "               A A               ", "               A A               ", "                                 ", "                                 ", "                                 ", "                                 ", "                                 ", "                                 ")
                    .aisle("                                 ", "                                 ", "                                 ", "                                 ", "                                 ", "               A A               ", "              AAAAA              ", "                D                ", "                F                ", "                F                ", "                                 ", "                                 ", "                                 ", "                                 ", "      A                   A      ", "     AA                   AA     ", "      ADFF             FFDA      ", "     AA                   AA     ", "      A                   A      ", "                                 ", "                                 ", "                                 ", "                                 ", "                F                ", "                F                ", "                D                ", "              AAAAA              ", "               A A               ", "                                 ", "                                 ", "                                 ", "                                 ", "                                 ")
                    .aisle("                                 ", "                                 ", "                                 ", "                                 ", "               A A               ", "               A A               ", "                D                ", "             GEEFEEG             ", "                                 ", "                                 ", "                                 ", "                                 ", "                                 ", "       G                 G       ", "       E                 E       ", "    AA E                 E AA    ", "      DF                 FD      ", "    AA E                 E AA    ", "       E                 E       ", "       G                 G       ", "                                 ", "                                 ", "                                 ", "                                 ", "                                 ", "             GEEFEEG             ", "                D                ", "               A A               ", "               A A               ", "                                 ", "                                 ", "                                 ", "                                 ")
                    .aisle("                                 ", "                                 ", "                                 ", "               A A               ", "              AAAAA              ", "                D                ", "                F                ", "                                 ", "                                 ", "                                 ", "                                 ", "                                 ", "                                 ", "                                 ", "    A                       A    ", "   AA                       AA   ", "    ADF                   FDA    ", "   AA                       AA   ", "    A                       A    ", "                                 ", "                                 ", "                                 ", "                                 ", "                                 ", "                                 ", "                                 ", "                F                ", "                D                ", "              AAAAA              ", "               A A               ", "                                 ", "                                 ", "                                 ")
                    .aisle("                                 ", "                                 ", "               A A               ", "               A A               ", "                D                ", "             GEEFEEG             ", "                                 ", "                                 ", "                                 ", "                                 ", "                                 ", "                                 ", "                                 ", "     G                     G     ", "     E                     E     ", "  AA E                     E AA  ", "    DF                     FD    ", "  AA E                     E AA  ", "     E                     E     ", "     G                     G     ", "                                 ", "                                 ", "                                 ", "                                 ", "                                 ", "                                 ", "                                 ", "             GEEFEEG             ", "                D                ", "               A A               ", "               A A               ", "                                 ", "                                 ")
                    .aisle("                                 ", "                                 ", "               A A               ", "                D                ", "                F                ", "                                 ", "                                 ", "                                 ", "                                 ", "                                 ", "                                 ", "                                 ", "                                 ", "                                 ", "                                 ", "  A                           A  ", "   DF                       FD   ", "  A                           A  ", "                                 ", "                                 ", "                                 ", "                                 ", "                                 ", "                                 ", "                                 ", "                                 ", "                                 ", "                                 ", "                F                ", "                D                ", "               A A               ", "                                 ", "                                 ")
                    .aisle("                                 ", "               A A               ", "               A A               ", "                D                ", "                F                ", "                                 ", "                                 ", "                                 ", "                                 ", "                                 ", "                                 ", "                                 ", "                                 ", "                                 ", "                                 ", " AA                           AA ", "   DF                       FD   ", " AA                           AA ", "                                 ", "                                 ", "                                 ", "                                 ", "                                 ", "                                 ", "                                 ", "                                 ", "                                 ", "                                 ", "                F                ", "                D                ", "               A A               ", "               A A               ", "                                 ")
                    .aisle("                                 ", "               A A               ", "                D                ", "                                 ", "                                 ", "                                 ", "                                 ", "                                 ", "                                 ", "                                 ", "                                 ", "                                 ", "                                 ", "                                 ", "                                 ", " A                             A ", "  D                           D  ", " A                             A ", "                                 ", "                                 ", "                                 ", "                                 ", "                                 ", "                                 ", "                                 ", "                                 ", "                                 ", "                                 ", "                                 ", "                                 ", "                D                ", "               A A               ", "                                 ")
                    .aisle("                                 ", "               A A               ", "                D                ", "                                 ", "                                 ", "                                 ", "                                 ", "                                 ", "                                 ", "                                 ", "                                 ", "                                 ", "                                 ", "                                 ", "                                 ", " A                             A ", "  D                           D  ", " A                             A ", "                                 ", "                                 ", "                                 ", "                                 ", "                                 ", "                                 ", "                                 ", "                                 ", "                                 ", "                                 ", "                                 ", "                                 ", "                D                ", "               A A               ", "                                 ")
                    .aisle("               A A               ", "               A A               ", "             DDDDDDD             ", "                                 ", "                                 ", "                                 ", "                                 ", "                                 ", "                                 ", "                                 ", "                                 ", "                                 ", "                                 ", "  D                           D  ", "  D                           D  ", "AAD                           DAA", "  D                           D  ", "AAD                           DAA", "  D                           D  ", "  D                           D  ", "                                 ", "                                 ", "                                 ", "                                 ", "                                 ", "                                 ", "                                 ", "                                 ", "                                 ", "                                 ", "             DDDDDDD             ", "               A A               ", "               A A               ")
                    .aisle("               A A               ", "              DDDDD              ", "            DD     DD            ", "                                 ", "                                 ", "       G                 G       ", "                                 ", "     G                     G     ", "                                 ", "                                 ", "                                 ", "                                 ", "  D                           D  ", "  D                           D  ", " D                             D ", "AD                             DA", " D                             D ", "AD                             DA", " D                             D ", "  D                           D  ", "  D                           D  ", "                                 ", "                                 ", "                                 ", "                                 ", "     G                     G     ", "                                 ", "       G                 G       ", "                                 ", "                                 ", "            DD     DD            ", "              DDDDD              ", "               A A               ")
                    .aisle("               A A               ", "             DDADADD             ", "            D  EEE  D            ", "                                 ", "      A                   A      ", "       E                 E       ", "    A                       A    ", "     E                     E     ", "                                 ", "                                 ", "                                 ", "                                 ", "  D                           D  ", " D                             D ", " D                             D ", "AAE                           EAA", " DE                           ED ", "AAE                           EAA", " D                             D ", " D                             D ", "  D                           D  ", "                                 ", "                                 ", "                                 ", "                                 ", "     E                     E     ", "    A                       A    ", "       E                 E       ", "      A                   A      ", "                                 ", "            D  EEE  D            ", "             DDADADD             ", "               A A               ")
                    .aisle("            AAAAAAAAA            ", "         AAAADAADAADAAAA         ", "       AAA  D EFFFE D  AAA       ", "      AA                 AA      ", "     AA                   AA     ", "    AA E                 E AA    ", "   AA                       AA   ", "  AA E                     E AA  ", "  A                           A  ", " AA                           AA ", " A                             A ", " A                             A ", "AAD                           DAA", "AD                             DA", "AAE                           EAA", "AAF                           FAA", "ADF                           FDA", "AAF                           FAA", "AAE                           EAA", "AD                             DA", "AAD                           DAA", " A                             A ", " A                             A ", " AA                           AA ", "  A                           A  ", "  AA E                     E AA  ", "   AA                       AA   ", "    AA E                 E AA    ", "     AA                   AA     ", "      AA                 AA      ", "       AAA  D EFFFE D  AAA       ", "         AAAADAADAADAAAA         ", "            AAAAAAAAA            ")
                    .aisle("               A A               ", "             DDDDDDD             ", "          DDD EFFFE DDD          ", "        DD             DD        ", "      ADFF             FFDA      ", "      DF                 FD      ", "    ADF                   FDA    ", "    DF                     FD    ", "   DF                       FD   ", "   DF                       FD   ", "  D                           D  ", "  D                           D  ", "  D                           D  ", " D                             D ", " DE                           ED ", "ADF                           FDA", " DF                           FD ", "ADF                           FDA", " DE                           ED ", " D                             D ", "  D                           D  ", "  D                           D  ", "  D                           D  ", "   DF                       FD   ", "   DF                       FD   ", "    DF                     FD    ", "    ADF                   FDA    ", "      DF                 FD      ", "      ADFF             FFDA      ", "        DD             DD        ", "          DDD EFFFE DDD          ", "             DDDDDDD             ", "               A A               ")
                    .aisle("            AAAAAAAAA            ", "         AAAADAADAADAAAA         ", "       AAA  D EFFFE D  AAA       ", "      AA                 AA      ", "     AA                   AA     ", "    AA E                 E AA    ", "   AA                       AA   ", "  AA E                     E AA  ", "  A                           A  ", " AA                           AA ", " A                             A ", " A                             A ", "AAD                           DAA", "AD                             DA", "AAE                           EAA", "AAF                           FAA", "ADF                           FDA", "AAF                           FAA", "AAE                           EAA", "AD                             DA", "AAD                           DAA", " A                             A ", " A                             A ", " AA                           AA ", "  A                           A  ", "  AA E                     E AA  ", "   AA                       AA   ", "    AA E                 E AA    ", "     AA                   AA     ", "      AA                 AA      ", "       AAA  D EFFFE D  AAA       ", "         AAAADAADAADAAAA         ", "            AAAAAAAAA            ")
                    .aisle("               A A               ", "             DDADADD             ", "            D  EEE  D            ", "                                 ", "      A                   A      ", "       E                 E       ", "    A                       A    ", "     E                     E     ", "                                 ", "                                 ", "                                 ", "                                 ", "  D                           D  ", " D                             D ", " D                             D ", "AAE                           EAA", " DE                           ED ", "AAE                           EAA", " D                             D ", " D                             D ", "  D                           D  ", "                                 ", "                                 ", "                                 ", "                                 ", "     E                     E     ", "    A                       A    ", "       E                 E       ", "      A                   A      ", "                                 ", "            D  EEE  D            ", "             DDADADD             ", "               A A               ")
                    .aisle("               A A               ", "              DDDDD              ", "            DD     DD            ", "                                 ", "                                 ", "       G                 G       ", "                                 ", "     G                     G     ", "                                 ", "                                 ", "                                 ", "                                 ", "  D                           D  ", "  D                           D  ", " D                             D ", "AD                             DA", " D                             D ", "AD                             DA", " D                             D ", "  D                           D  ", "  D                           D  ", "                                 ", "                                 ", "                                 ", "                                 ", "     G                     G     ", "                                 ", "       G                 G       ", "                                 ", "                                 ", "            DD     DD            ", "              DDDDD              ", "               A A               ")
                    .aisle("               A A               ", "               A A               ", "             DDDDDDD             ", "                                 ", "                                 ", "                                 ", "                                 ", "                                 ", "                                 ", "                                 ", "                                 ", "                                 ", "                                 ", "  D                           D  ", "  D                           D  ", "AAD                           DAA", "  D                           D  ", "AAD                           DAA", "  D                           D  ", "  D                           D  ", "                                 ", "                                 ", "                                 ", "                                 ", "                                 ", "                                 ", "                                 ", "                                 ", "                                 ", "                                 ", "             DDDDDDD             ", "               A A               ", "               A A               ")
                    .aisle("                                 ", "               A A               ", "                D                ", "                                 ", "                                 ", "                                 ", "                                 ", "                                 ", "                                 ", "                                 ", "                                 ", "                                 ", "                                 ", "                                 ", "                                 ", " A                             A ", "  D                           D  ", " A                             A ", "                                 ", "                                 ", "                                 ", "                                 ", "                                 ", "                                 ", "                                 ", "                                 ", "                                 ", "                                 ", "                                 ", "                                 ", "                D                ", "               A A               ", "                                 ")
                    .aisle("                                 ", "               A A               ", "                D                ", "                                 ", "                                 ", "                                 ", "                                 ", "                                 ", "                                 ", "                                 ", "                                 ", "                                 ", "                                 ", "                                 ", "                                 ", " A                             A ", "  D                           D  ", " A                             A ", "                                 ", "                                 ", "                                 ", "                                 ", "                                 ", "                                 ", "                                 ", "                                 ", "                                 ", "                                 ", "                                 ", "                                 ", "                D                ", "               A A               ", "                                 ")
                    .aisle("                                 ", "               A A               ", "               A A               ", "                D                ", "                F                ", "                                 ", "                                 ", "                                 ", "                                 ", "                                 ", "                                 ", "                                 ", "                                 ", "                                 ", "                                 ", " AA                           AA ", "   DF                       FD   ", " AA                           AA ", "                                 ", "                                 ", "                                 ", "                                 ", "                                 ", "                                 ", "                                 ", "                                 ", "                                 ", "                                 ", "                F                ", "                D                ", "               A A               ", "               A A               ", "                                 ")
                    .aisle("                                 ", "                                 ", "               A A               ", "                D                ", "                F                ", "                                 ", "                                 ", "                                 ", "                                 ", "                                 ", "                                 ", "                                 ", "                                 ", "                                 ", "                                 ", "  A                           A  ", "   DF                       FD   ", "  A                           A  ", "                                 ", "                                 ", "                                 ", "                                 ", "                                 ", "                                 ", "                                 ", "                                 ", "                                 ", "                                 ", "                F                ", "                D                ", "               A A               ", "                                 ", "                                 ")
                    .aisle("                                 ", "                                 ", "               A A               ", "               A A               ", "                D                ", "             GEEFEEG             ", "                                 ", "                                 ", "                                 ", "                                 ", "                                 ", "                                 ", "                                 ", "     G                     G     ", "     E                     E     ", "  AA E                     E AA  ", "    DF                     FD    ", "  AA E                     E AA  ", "     E                     E     ", "     G                     G     ", "                                 ", "                                 ", "                                 ", "                                 ", "                                 ", "                                 ", "                                 ", "             GEEFEEG             ", "                D                ", "               A A               ", "               A A               ", "                                 ", "                                 ")
                    .aisle("                                 ", "                                 ", "                                 ", "               A A               ", "              AAAAA              ", "                D                ", "                F                ", "                                 ", "                                 ", "                                 ", "                                 ", "                                 ", "                                 ", "                                 ", "    A                       A    ", "   AA                       AA   ", "    ADF                   FDA    ", "   AA                       AA   ", "    A                       A    ", "                                 ", "                                 ", "                                 ", "                                 ", "                                 ", "                                 ", "                                 ", "                F                ", "                D                ", "              AAAAA              ", "               A A               ", "                                 ", "                                 ", "                                 ")
                    .aisle("                                 ", "                                 ", "                                 ", "                                 ", "               A A               ", "               A A               ", "                D                ", "             GEEFEEG             ", "                                 ", "                                 ", "                                 ", "                                 ", "                                 ", "       G                 G       ", "       E                 E       ", "    AA E                 E AA    ", "      DF                 FD      ", "    AA E                 E AA    ", "       E                 E       ", "       G                 G       ", "                                 ", "                                 ", "                                 ", "                                 ", "                                 ", "             GEEFEEG             ", "                D                ", "               A A               ", "               A A               ", "                                 ", "                                 ", "                                 ", "                                 ")
                    .aisle("                                 ", "                                 ", "                                 ", "                                 ", "                                 ", "               A A               ", "              AAAAA              ", "                D                ", "                F                ", "                F                ", "                                 ", "                                 ", "                                 ", "                                 ", "      A                   A      ", "     AA                   AA     ", "      ADFF             FFDA      ", "     AA                   AA     ", "      A                   A      ", "                                 ", "                                 ", "                                 ", "                                 ", "                F                ", "                F                ", "                D                ", "              AAAAA              ", "               A A               ", "                                 ", "                                 ", "                                 ", "                                 ", "                                 ")
                    .aisle("                                 ", "                                 ", "                                 ", "                                 ", "                                 ", "                                 ", "               A A               ", "               A A               ", "                D                ", "                D                ", "                                 ", "                                 ", "                                 ", "                                 ", "                                 ", "      AA                 AA      ", "        DD             DD        ", "      AA                 AA      ", "                                 ", "                                 ", "                                 ", "                                 ", "                                 ", "                D                ", "                D                ", "               A A               ", "               A A               ", "                                 ", "                                 ", "                                 ", "                                 ", "                                 ", "                                 ")
                    .aisle("                                 ", "                                 ", "                                 ", "                                 ", "                                 ", "                                 ", "                                 ", "               A A               ", "               A A               ", "               A A               ", "                D                ", "                D                ", "             DDDDDDD             ", "            DD     DD            ", "            D  EEE  D            ", "       AAA  D EFFFE D  AAA       ", "          DDD EFFFE DDD          ", "       AAA  D EFFFE D  AAA       ", "            D  EEE  D            ", "            DD     DD            ", "             DDDDDDD             ", "                D                ", "                D                ", "               A A               ", "               A A               ", "               A A               ", "                                 ", "                                 ", "                                 ", "                                 ", "                                 ", "                                 ", "                                 ")
                    .aisle("                                 ", "                                 ", "                                 ", "                                 ", "                                 ", "                                 ", "                                 ", "                                 ", "                                 ", "               A A               ", "               A A               ", "               A A               ", "               A A               ", "              DDDDD              ", "             DDADADD             ", "         AAAADAADAADAAAA         ", "             DDDDDDD             ", "         AAAADAADAADAAAA         ", "             DDADADD             ", "              DDDDD              ", "               A A               ", "               A A               ", "               A A               ", "               A A               ", "                                 ", "                                 ", "                                 ", "                                 ", "                                 ", "                                 ", "                                 ", "                                 ", "                                 ")
                    .aisle("                                 ", "                                 ", "                                 ", "                                 ", "                                 ", "                                 ", "                                 ", "                                 ", "                                 ", "                                 ", "                                 ", "                                 ", "             AAAAAAA             ", "            AABBBBBAA            ", "            ABBBBBBBA            ", "            ABBAAABBA            ", "            ABBA~ABBA            ", "            ABBAAABBA            ", "            ABBBBBBBA            ", "            AABBBBBAA            ", "             AAAAAAA             ", "                                 ", "                                 ", "                                 ", "                                 ", "                                 ", "                                 ", "                                 ", "                                 ", "                                 ", "                                 ", "                                 ", "                                 ")
                    .where('~', controller(blocks(definition.get())))
                    .where('A', blocks(GTEBlocks.DIMENSIONALLY_TRANSCENDENT_CASING.get()))
                    .where('B', blocks(GTBlocks.HIGH_POWER_CASING.get())
                            .or(abilities(EXPORT_ITEMS).setPreviewCount(1))
                            .or(abilities(IMPORT_ITEMS).setPreviewCount(1))
                            .or(abilities(EXPORT_FLUIDS).setPreviewCount(1))
                            .or(abilities(IMPORT_FLUIDS).setPreviewCount(1)))
                    .where('D', blocks(GTEBlocks.DIMENSION_INJECTION_CASING.get()))
                    .where('E', blocks(GTEBlocks.DIMENSIONAL_BRIDGE_CASING.get()))
                    .where('F', blocks(GTEBlocks.SPACETIME_COMPRESSION_FIELD_GENERATOR.get()))
                    .where('G', blocks(GTEBlocks.DIMENSIONAL_STABILITY_CASING.get()))
                    .where(' ', any())
                    .build())
            .renderer(EyeOfHarmonyRenderer::new)
            .hasTESR(true)
            .register();

    MultiblockMachineDefinition SPACE_PROBE_SURFACE_RECEPTION = multiblock("space_probe_surface_reception", "宇宙探测器地面接收单元", SpaceProbeSurfaceReceptionMachine::new)
            .nonYAxisRotation()
            .recipe(GTERecipeTypes.SPACE_PROBE_SURFACE_RECEPTION_RECIPES)
            .tooltipsText("It Can Only Operate On Space Station", "只能运行在空间站")
            .tooltipsText("If there are unused Dyson spheres in the galaxy, attempt to connect to them and increase production based on the number of Dyson sphere modules, This operation will not damage the Dyson sphere.", "如果该星系存在未使用的戴森球，则尝试连接，根据戴森球模块数量提升产出，该操作不会损坏戴森球")
            .customTooltipsBuilder(true, false, false)
            .alwaysTryModifyRecipe(true)
            .block(GCYMBlocks.CASING_ATOMIC)
            .pattern(definition -> FactoryBlockPattern.start()
                    .aisle("                                     ", "                                     ", "                                     ", "                                     ", "                                     ", "                                     ", "                                     ", "                                     ", "                                     ", "                                     ", "                                     ", "                                     ", "                                     ", "                                     ", "                                     ", "                                     ", "                                     ", "                                     ", "                                     ", "                                     ", "                                     ", "                                     ", "                                     ", "                                     ", "                                     ", "                                     ", "                                     ", "                                     ", "                                     ", "                                     ")
                    .aisle("                                     ", "                                     ", "                                     ", "                                     ", "                                     ", "                                     ", "                                     ", "                                     ", "                                     ", "                                     ", "                                     ", "                                     ", "                                     ", "                                     ", "                                     ", "              AAAAAAAAA              ", "                                     ", "                                     ", "                                     ", "                                     ", "                                     ", "                                     ", "                                     ", "                                     ", "                                     ", "                                     ", "                                     ", "                                     ", "                                     ", "                                     ")
                    .aisle("                                     ", "                                     ", "                                     ", "                                     ", "                                     ", "                                     ", "                                     ", "                                     ", "                                     ", "                                     ", "                                     ", "                                     ", "                                     ", "                                     ", "                                     ", "          AAAAAAAAAAAAAAAAA          ", "                                     ", "                                     ", "                                     ", "                                     ", "                                     ", "                                     ", "                                     ", "                                     ", "                                     ", "                                     ", "                                     ", "                                     ", "                                     ", "                                     ")
                    .aisle("                 BBB                 ", "                                     ", "                                     ", "                                     ", "                                     ", "                                     ", "                                     ", "                                     ", "                                     ", "                                     ", "                                     ", "                                     ", "                                     ", "                                     ", "                                     ", "        AAAAAAAAAAAAAAAAAAAAA        ", "                                     ", "                                     ", "                                     ", "                                     ", "                                     ", "                                     ", "                                     ", "                                     ", "                                     ", "                                     ", "                                     ", "                                     ", "                                     ", "                                     ")
                    .aisle("                  B                  ", "                  B                  ", "                                     ", "                                     ", "                                     ", "                                     ", "                                     ", "                                     ", "                                     ", "                                     ", "                                     ", "                                     ", "                                     ", "                                     ", "           AAAAAAAAAAAAAAA           ", "       AAAA       C       AAAA       ", "                                     ", "                                     ", "                                     ", "                                     ", "                                     ", "                                     ", "                                     ", "                                     ", "                                     ", "                                     ", "                                     ", "                                     ", "                                     ", "                                     ")
                    .aisle("                                     ", "                  B                  ", "                  B                  ", "                                     ", "                                     ", "                                     ", "                                     ", "                                     ", "                                     ", "                                     ", "                                     ", "                                     ", "                                     ", "            AAAAAAAAAAAAA            ", "         AAA      C      AAA         ", "      AAA                   AAA      ", "                                     ", "                                     ", "                                     ", "                                     ", "                                     ", "                                     ", "                                     ", "                                     ", "                                     ", "                                     ", "                                     ", "                                     ", "                                     ", "                                     ")
                    .aisle("                                     ", "                                     ", "                  B                  ", "                  B                  ", "                                     ", "                                     ", "                                     ", "                                     ", "                                     ", "                                     ", "                                     ", "                                     ", "             AAAAAAAAAAA             ", "          AAA     C     AAA          ", "        AA                 AA        ", "     AAA          C          AAA     ", "                                     ", "                                     ", "                                     ", "                                     ", "                                     ", "                                     ", "                                     ", "                                     ", "                                     ", "                                     ", "                                     ", "                                     ", "                                     ", "                                     ")
                    .aisle("                                     ", "                                     ", "                                     ", "                  B                  ", "                BBBBB                ", "                  B                  ", "                                     ", "                                     ", "                                     ", "                                     ", "                                     ", "                                     ", "           AAAAAAAAAAAAAAA           ", "         AA       C       AA         ", "       AA                   AA       ", "    AAA                       AAA    ", "                  C                  ", "                                     ", "                                     ", "                                     ", "                                     ", "                                     ", "                                     ", "                                     ", "                                     ", "                                     ", "                                     ", "                                     ", "                                     ", "                                     ")
                    .aisle("                                     ", "                                     ", "                                     ", "                                     ", "                D   D                ", "                D B D                ", "           D             D           ", "           D             D           ", "          DD             DD          ", "          D               D          ", "         DD               DD         ", "         D    AAAAAAAAA    D         ", "        DBAAAA    C    AAAABD        ", "       BAA                 AAB       ", "      AA                     AA      ", "   AAA                         AAA   ", "                                     ", "                  C                  ", "                                     ", "                                     ", "                                     ", "                                     ", "                                     ", "                                     ", "                                     ", "                                     ", "                                     ", "                                     ", "                                     ", "                                     ")
                    .aisle("                                     ", "                                     ", "            B           B            ", "            B           B            ", "            DB          D            ", "            D    DBD    D            ", "            D    D D    D            ", "                                     ", "                  D                  ", "                                     ", "                                     ", "            AAAAAAAAAAAAA            ", "       DBAAA      C      AAABD       ", "       AA                   AA       ", "     AA                       AA     ", "  AAA                           AAA  ", "                                     ", "                                     ", "                  C                  ", "                                     ", "                                     ", "                                     ", "                                     ", "                                     ", "                                     ", "                                     ", "                                     ", "                                     ", "                                     ", "                                     ")
                    .aisle("                                     ", "             B         B             ", "             B         B             ", "                EEEEE                ", "            BB  EEEEE   B            ", "                  E                  ", "                  D                  ", "                  D                  ", "               FFFFFFF               ", "               FFFFFFF               ", "       D       CCCCCCC       D       ", "       D   AAAA   C   AAAA   D       ", "       BAAA       C       AAAB       ", "      AA                     AA      ", "    AA                         AA    ", "  AA                             AA  ", "                                     ", "                                     ", "                                     ", "                  C                  ", "                                     ", "                                     ", "                                     ", "                                     ", "                                     ", "                                     ", "                                     ", "                                     ", "                                     ", "                                     ")
                    .aisle("              B       B              ", "              B       B              ", "                  E                  ", "              EEEEEEEEE              ", "            BBEE     EE B            ", "                EEEEE                ", "                                     ", "                                     ", "       D     FFFFFFFFFFF     D       ", "       D     FFFFFFFFFFF     D       ", "       D     CCCCCCCCCCC     D       ", "          AAA     C     AAA          ", "       AAA                 AAA       ", "     AA                       AA     ", "    A                           A    ", " AAA                             AAA ", "                                     ", "                                     ", "                                     ", "                                     ", "                  C                  ", "                                     ", "                                     ", "                                     ", "                                     ", "                                     ", "                                     ", "                                     ", "                                     ", "                                     ")
                    .aisle("                                     ", "                                     ", "              EEEEEEEEE              ", "            GG         GG            ", "            GG         GG            ", "              EEEEEEEEE              ", "       D          E          D       ", "       D                     D       ", "       D    FFFFFFFFFFFFF    D       ", "            FFFFFFFFFFFFF            ", "            CCCCCCCCCCCCC            ", "         AAA             AAA         ", "      AAA                   AAA      ", "     A                         A     ", "   AA                           AA   ", " AA                               AA ", "                                     ", "                                     ", "                                     ", "                                     ", "                                     ", "                  C                  ", "                                     ", "                                     ", "                                     ", "                                     ", "                                     ", "                                     ", "                                     ", "                                     ")
                    .aisle("                                     ", "                                     ", "        B    EEHHHHHHHEE    B        ", "        B  GG           GG  B        ", "        DBBGG           GGBBD        ", "        D   GGEEE   EEEGG   D        ", "        D        EEE        D        ", "                                     ", "           FFFFIIIIIIIFFFF           ", "           FFFFIIIIIIIFFFF           ", "           CCCCCCCCCCCCCCC           ", "        AAA               AAA        ", "      AA                     AA      ", "    AA                         AA    ", "   A                             A   ", " AA                               AA ", "                                     ", "                                     ", "                                     ", "                                     ", "                                     ", "                                     ", "                  C                  ", "                                     ", "                                     ", "                                     ", "                                     ", "                                     ", "                                     ", "                                     ")
                    .aisle("                                     ", "         B                 B         ", "         B  EEJJJJJJJJJEE  B         ", "           G             G           ", "        BBBG             G  B        ", "            GG         GG            ", "              GEEEEEEEG              ", "                                     ", "          FFFDDDDDDDDDDDFFF          ", "          FFFDDDDDDDDDDDFFF          ", "          CCCCCCCCCCCCCCCCC          ", "        AA                 AA        ", "     AAA                     AAA     ", "    A                           A    ", "   A                             A   ", " AA                               AA ", "                                     ", "                                     ", "                                     ", "                                     ", "                                     ", "                                     ", "                CCCCC                ", "                                     ", "                                     ", "                                     ", "                                     ", "                                     ", "                                     ", "                                     ")
                    .aisle("          B               B          ", "          B               B          ", "           EEJJJJJJJJJJJEE           ", "          E               E          ", "          E               E          ", "           EE           EE           ", "             GGGEEEEEGGG             ", "                  E                  ", "          FFFDDDDDDDDDDDFFF          ", "          FFFDDDDDDDDDDDFFF          ", "          CCCCCCCCCCCCCCCCC          ", "       AAA                 AAA       ", "     AA                       AA     ", "    A                           A    ", "   A                             A   ", "AAA                               AAA", "                                     ", "                                     ", "                                     ", "                                     ", "                                     ", "                 CCC                 ", "               CCKKKCC               ", "                                     ", "                                     ", "                                     ", "                                     ", "                                     ", "                                     ", "                                     ")
                    .aisle("                                     ", "                                     ", "           EHJJJJJJJJJJJHE           ", "          E               E          ", "       B  E               E          ", "           EE           EE           ", "             EGG     GGE             ", "               GGEEEGG               ", "         FFFIDDFFFFFFFDDIFFF         ", "         FFFIDDFFFFFFFDDIFFF         ", "         CCCCCCCCCCCCCCCCCCC         ", "       AA                   AA       ", "     AA                       AA     ", "    A                           A    ", "   A                             A   ", "AAA                               AAA", "                                     ", "                                     ", "                                     ", "                                     ", "                                     ", "                CCDCC                ", "              CCKKKKKCC              ", "                                     ", "                                     ", "                                     ", "                                     ", "                                     ", "                                     ", "                                     ")
                    .aisle("                                     ", "                                     ", "           EHJJJJJJJJJJJHE           ", "         EE               EE         ", "      BD E                 E DB      ", "       D  EEE           EEE  D       ", "             EE       EE             ", "               GEEEEEG               ", "         FFFIDDFFFFFFFDDIFFF         ", "         FFFIDDFFFFFFFDDIFFF         ", "         CCCCCCCCCCCCCCCCCCC         ", "       AA                   AA       ", "     AA                       AA     ", "    A                           A    ", "   A                             A   ", "AAA                               AAA", "                                     ", "                                     ", "                                     ", "                                     ", "                  C                  ", "               CCDDDCC               ", "             CCKKKKKKKCC             ", "                                     ", "                                     ", "                                     ", "                                     ", "                                     ", "                                     ", "                                     ")
                    .aisle("                                  B  ", "                                     ", "           EHJJJJJJJJJJJHE           ", "         EE               EE         ", "      B  E                 E  B      ", "        D EE             EE D        ", "        D   EEE       EEE   D        ", "               EEEEEEE      D        ", "         FFFIDDFFFFFFFDDIFFF         ", "         FFFIDDFFFFFFFDDIFFF         ", "         CCCCCCCCCCCCCCCCCCC         ", "       AA                   AA       ", "     AA                       AA     ", "    A                           A    ", "   A                             A   ", "AAA                               AAA", "                                     ", "                                     ", "                                     ", "                                     ", "                 CCC                 ", "              CCDDDDDCC              ", "             CKKKKKKKKKC             ", "                  L                  ", "                  L                  ", "                                     ", "                                     ", "                                     ", "                                     ", "                                     ")
                    .aisle("  BB                             BB  ", "   BB                           BB   ", "    BB    EEHJJJJJJJJJJJHEE    BB    ", "     BB  EE       M       EE  BB     ", "      B  E        M        E  B      ", "      BBBEEE      M      EEEBBB      ", "         D EEEE   M   EEEE D         ", "         D    EEEEMEEEE    D         ", "        DFFFIDDFFFMFFFDDIFFFD        ", "         FFFIDDFFFMFFFDDIFFF         ", "         CCCCCCCCCCCCCCCCCCC         ", "       AACC               CCAA       ", "     AACCC                 CCCAA     ", "    ACC                       CCA    ", "   AC                           CA   ", "AAAC C                         C CAAA", "      C                       C      ", "       C                     C       ", "        C                   C        ", "         C                 C         ", "          C     CCCCC     C          ", "           C  CDDDDDDDC  C           ", "            CCKKKKKKKKKCC            ", "                 LLL                 ", "                 LLL                 ", "                  L                  ", "                  L                  ", "                  L                  ", "                  L                  ", "                  L                  ")
                    .aisle("                                  B  ", "                                     ", "           EHJJJJJJJJJJJHE           ", "         EE               EE         ", "      B  E                 E  B      ", "        D EE             EE D        ", "        D   EEE       EEE   D        ", "               EEEEEEE      D        ", "         FFFIDDFFFFFFFDDIFFF         ", "         FFFIDDFFFFFFFDDIFFF         ", "         CCCCCCCCCCCCCCCCCCC         ", "       AA                   AA       ", "     AA                       AA     ", "    A                           A    ", "   A                             A   ", "AAA                               AAA", "                                     ", "                                     ", "                                     ", "                                     ", "                 CCC                 ", "              CCDDDDDCC              ", "             CKKKKKKKKKC             ", "                  L                  ", "                  L                  ", "                                     ", "                                     ", "                                     ", "                                     ", "                                     ")
                    .aisle("                                     ", "                                     ", "           EHJJJJJJJJJJJHE           ", "         EE               EE         ", "      BD E                 E DB      ", "       D  EEE           EEE  D       ", "             EE       EE             ", "               GEEEEEG               ", "         FFFIDDFFFFFFFDDIFFF         ", "         FFFIDDFFFFFFFDDIFFF         ", "         CCCCCCCCCCCCCCCCCCC         ", "       AA                   AA       ", "     AA                       AA     ", "    A                           A    ", "   A                             A   ", "AAA                               AAA", "                                     ", "                                     ", "                                     ", "                                     ", "                  C                  ", "               CCDDDDC               ", "             CCKKKKKKKCC             ", "                                     ", "                                     ", "                                     ", "                                     ", "                                     ", "                                     ", "                                     ")
                    .aisle("                                     ", "                                     ", "           EHJJJJJJJJJJJHE           ", "          E               E          ", "       B  E               E          ", "           EE           EE           ", "             EGG     GGE             ", "               GGEEEGG               ", "         FFFIDDFFFFFFFDDIFFF         ", "         FFFIDDFFFFFFFDDIFFF         ", "         CCCCCCCCCCCCCCCCCCC         ", "       AA                   AA       ", "     AA                       AA     ", "    A                           A    ", "   A                             A   ", "AAA                               AAA", "                                     ", "                                     ", "                                     ", "                                     ", "                                     ", "                CCDCC                ", "              CCKKKKKCC              ", "                                     ", "                                     ", "                                     ", "                                     ", "                                     ", "                                     ", "                                     ")
                    .aisle("          B               B          ", "          B               B          ", "           EEJJJJJJJJJJJEE           ", "          E               E          ", "          E               E          ", "           EE           EE           ", "             GGGEEEEEGGG             ", "                  E                  ", "          FFFDDDDDDDDDDDFFF          ", "          FFFDDDDDDDDDDDFFF          ", "          CCCCCCCCCCCCCCCCC          ", "       AAA                 AAA       ", "     AA                       AA     ", "    A                           A    ", "   A                             A   ", "AAA                               AAA", "                                     ", "                                     ", "                                     ", "                                     ", "                                     ", "                 CCC                 ", "               CCKKKCC               ", "                                     ", "                                     ", "                                     ", "                                     ", "                                     ", "                                     ", "                                     ")
                    .aisle("                                     ", "         B                 B         ", "         B  bEJJJJJJJJJEb  B         ", "           G             G           ", "        B  G             G           ", "            GG         GG            ", "              GEEEEEEEG              ", "                                     ", "          FFFDDDDDDDDDDDFFF          ", "          FFFDDDDDDDDDDDFFF          ", "          CCCCCCCCCCCCCCCCC          ", "        AA                 AA        ", "     AAA                     AAA     ", "    A                           A    ", "   A                             A   ", " AA                               AA ", "                                     ", "                                     ", "                                     ", "                                     ", "                                     ", "                                     ", "                CCCCC                ", "                                     ", "                                     ", "                                     ", "                                     ", "                                     ", "                                     ", "                                     ")
                    .aisle("                                     ", "                                     ", "        B    bEHHHHHHHEb    B        ", "        B  GG           GG  B        ", "        DBBGG           GGBBD        ", "        D   GGEEE   EEEGG   D        ", "        D        EEE        D        ", "                                     ", "           FFFFIIIIIIIFFFF           ", "           FFFFIIIIIIIFFFF           ", "           CCCCCCCCCCCCCCC           ", "        AAA               AAA        ", "      AA                     AA      ", "    AA                         AA    ", "   A                             A   ", " AA                               AA ", "                                     ", "                                     ", "                                     ", "                                     ", "                                     ", "                                     ", "                  C                  ", "                                     ", "                                     ", "                                     ", "                                     ", "                                     ", "                                     ", "                                     ")
                    .aisle("                                     ", "                                     ", "              bbbbEbbbb              ", "            GG         GG            ", "            GG         GG            ", "              EEEEEEEEE              ", "       D          E          D       ", "       D                     D       ", "       D    FFFFFFFFFFFFF    D       ", "            FFFFFFFFFFFFF            ", "            CCCCCCCCCCCCC            ", "         AAA             AAA         ", "      AAA                   AAA      ", "     A                         A     ", "   AA                           AA   ", " AA                               AA ", "                                     ", "                                     ", "                                     ", "                                     ", "                                     ", "                  C                  ", "                                     ", "                                     ", "                                     ", "                                     ", "                                     ", "                                     ", "                                     ", "                                     ")
                    .aisle("              B       B              ", "              B       B              ", "                  ~                  ", "              EEEEEEEEE              ", "            B EE     EE B            ", "                EEEEE                ", "                                     ", "                                     ", "       D     FFFFFFFFFFF     D       ", "       D     FFFFFFFFFFF     D       ", "       D     CCCCCCCCCCC     D       ", "          AAA     C     AAA          ", "       AAA                 AAA       ", "     AA                       AA     ", "    A                           A    ", " AAA                             AAA ", "                                     ", "                                     ", "                                     ", "                                     ", "                  C                  ", "                                     ", "                                     ", "                                     ", "                                     ", "                                     ", "                                     ", "                                     ", "                                     ", "                                     ")
                    .aisle("                                     ", "             B         B             ", "             B         B             ", "                bbbbb                ", "            B   EEEEE   B            ", "                  E                  ", "                  D                  ", "                  D                  ", "               FFFFFFF               ", "               FFFFFFF               ", "       D       CCCCCCC       D       ", "       D   AAAA   C   AAAA   D       ", "       BAAA       C       AAAB       ", "      AA                     AA      ", "    AA                         AA    ", "  AA                             AA  ", "                                     ", "                                     ", "                                     ", "                  C                  ", "                                     ", "                                     ", "                                     ", "                                     ", "                                     ", "                                     ", "                                     ", "                                     ", "                                     ", "                                     ")
                    .aisle("                                     ", "                                     ", "            B           B            ", "            B           B            ", "            D          BD            ", "            D    DBD    D            ", "            D    D D    D            ", "                 D D                 ", "                  D                  ", "                                     ", "                                     ", "            AAAAAAAAAAAAA            ", "       DBAAA      C      AAABD       ", "       AA                   AA       ", "     AA                       AA     ", "  AAA                           AAA  ", "                                     ", "                                     ", "                  C                  ", "                                     ", "                                     ", "                                     ", "                                     ", "                                     ", "                                     ", "                                     ", "                                     ", "                                     ", "                                     ", "                                     ")
                    .aisle("                                     ", "                                     ", "                                     ", "                                     ", "                D   D                ", "                D B D                ", "           D             D           ", "           D             D           ", "          DD             DD          ", "          D               D          ", "         DD               DD         ", "         D    AAAAAAAAA    D         ", "        DBAAAA    C    AAAABD        ", "       BAA                 AAB       ", "      AA                     AA      ", "   AAA                         AAA   ", "                                     ", "                  C                  ", "                                     ", "                                     ", "                                     ", "                                     ", "                                     ", "                                     ", "                                     ", "                                     ", "                                     ", "                                     ", "                                     ", "                                     ")
                    .aisle("                                     ", "                                     ", "                                     ", "                  B                  ", "                BBBBB                ", "                  B                  ", "                                     ", "                                     ", "                                     ", "                                     ", "                                     ", "                                     ", "           AAAAAAAAAAAAAAA           ", "         AA       C       AA         ", "       AA                   AA       ", "    AAA                       AAA    ", "                  C                  ", "                                     ", "                                     ", "                                     ", "                                     ", "                                     ", "                                     ", "                                     ", "                                     ", "                                     ", "                                     ", "                                     ", "                                     ", "                                     ")
                    .aisle("                                     ", "                                     ", "                  B                  ", "                  B                  ", "                                     ", "                                     ", "                                     ", "                                     ", "                                     ", "                                     ", "                                     ", "                                     ", "             AAAAAAAAAAA             ", "          AAA     C     AAA          ", "        AA                 AA        ", "     AAA          C          AAA     ", "                                     ", "                                     ", "                                     ", "                                     ", "                                     ", "                                     ", "                                     ", "                                     ", "                                     ", "                                     ", "                                     ", "                                     ", "                                     ", "                                     ")
                    .aisle("                                     ", "                  B                  ", "                  B                  ", "                                     ", "                                     ", "                                     ", "                                     ", "                                     ", "                                     ", "                                     ", "                                     ", "                                     ", "                                     ", "            AAAAAAAAAAAAA            ", "         AAA      C      AAA         ", "      AAA                   AAA      ", "                                     ", "                                     ", "                                     ", "                                     ", "                                     ", "                                     ", "                                     ", "                                     ", "                                     ", "                                     ", "                                     ", "                                     ", "                                     ", "                                     ")
                    .aisle("                  B                  ", "                  B                  ", "                                     ", "                                     ", "                                     ", "                                     ", "                                     ", "                                     ", "                                     ", "                                     ", "                                     ", "                                     ", "                                     ", "                                     ", "           AAAAAAAAAAAAAAA           ", "       AAAA       C       AAAA       ", "                                     ", "                                     ", "                                     ", "                                     ", "                                     ", "                                     ", "                                     ", "                                     ", "                                     ", "                                     ", "                                     ", "                                     ", "                                     ", "                                     ")
                    .aisle("                 BBB                 ", "                                     ", "                                     ", "                                     ", "                                     ", "                                     ", "                                     ", "                                     ", "                                     ", "                                     ", "                                     ", "                                     ", "                                     ", "                                     ", "                                     ", "        AAAAAAAAAAAAAAAAAAAAA        ", "                                     ", "                                     ", "                                     ", "                                     ", "                                     ", "                                     ", "                                     ", "                                     ", "                                     ", "                                     ", "                                     ", "                                     ", "                                     ", "                                     ")
                    .aisle("                                     ", "                                     ", "                                     ", "                                     ", "                                     ", "                                     ", "                                     ", "                                     ", "                                     ", "                                     ", "                                     ", "                                     ", "                                     ", "                                     ", "                                     ", "          AAAAAAAAAAAAAAAAA          ", "                                     ", "                                     ", "                                     ", "                                     ", "                                     ", "                                     ", "                                     ", "                                     ", "                                     ", "                                     ", "                                     ", "                                     ", "                                     ", "                                     ")
                    .aisle("                                     ", "                                     ", "                                     ", "                                     ", "                                     ", "                                     ", "                                     ", "                                     ", "                                     ", "                                     ", "                                     ", "                                     ", "                                     ", "                                     ", "                                     ", "              AAAAAAAAA              ", "                                     ", "                                     ", "                                     ", "                                     ", "                                     ", "                                     ", "                                     ", "                                     ", "                                     ", "                                     ", "                                     ", "                                     ", "                                     ", "                                     ")
                    .where('~', controller(blocks(definition.get())))
                    .where('A', blocks(ChemicalHelper.getBlock(TagPrefix.block, GTMaterials.Neutronium)))
                    .where('B', blocks(GTEBlocks.NAQUADAH_REINFORCED_PLANT_CASING.get()))
                    .where('C', blocks(GTEBlocks.HIGH_PRESSURE_RESISTANT_CASING.get()))
                    .where('D', blocks(ChemicalHelper.getBlock(TagPrefix.frameGt, GTMaterials.Neutronium)))
                    .where('E', blocks(GCYMBlocks.CASING_ATOMIC.get()))
                    .where('F', blocks(GTEBlocks.HYPER_MECHANICAL_CASING.get()))
                    .where('G', blocks(GTEBlocks.NEUTRONIUM_STABLE_CASING.get()))
                    .where('H', blocks(GTEBlocks.HYPER_CORE.get()))
                    .where('I', blocks(GCYMBlocks.HEAT_VENT.get()))
                    .where('J', blocks(GTEBlocks.ANTIFREEZE_HEATPROOF_MACHINE_CASING.get()))
                    .where('K', blocks(GTBlocks.HIGH_POWER_CASING.get()))
                    .where('L', blocks(ChemicalHelper.getBlock(TagPrefix.frameGt, GTEMaterials.BlackTitanium)))
                    .where('M', blocks(GTEBlocks.AMPROSIUM_ACTIVE_CASING.get()))
                    .where('b', blocks(GCYMBlocks.CASING_ATOMIC.get())
                            .or(autoAbilities(definition.getRecipeTypes()))
                            .or(abilities(MAINTENANCE).setExactLimit(1))
                            .or(abilities(COMPUTATION_DATA_RECEPTION).setExactLimit(1)))
                    .where(' ', any())
                    .build())
