package org.gte.gtecore.common.data.machines;

import org.gte.gtecore.GTECore;
import org.gte.gtecore.api.machine.feature.multiblock.ICoilMachine;
import org.gte.gtecore.api.machine.multiblock.*;
import org.gte.gtecore.api.machine.part.GTEPartAbility;
import org.gte.gtecore.api.machine.trait.IEnhancedRecipeLogic;
import org.gte.gtecore.api.pattern.GTEPredicates;
import org.gte.gtecore.common.data.*;
import org.gte.gtecore.common.machine.multiblock.electric.FishingGroundMachine;
import org.gte.gtecore.common.machine.multiblock.electric.StellarForgeMachine;
import org.gte.gtecore.common.machine.multiblock.electric.gcym.GCYMMultiblockMachine;
import org.gte.gtecore.common.machine.multiblock.electric.voidseries.VoidFluidDrillingRigMachine;
import org.gte.gtecore.common.machine.multiblock.electric.voidseries.VoidMinerMachine;
import org.gte.gtecore.common.machine.multiblock.noenergy.AdvancedPrimitiveBlastFurnaceMachine;
import org.gte.gtecore.common.machine.multiblock.steam.*;

import com.gregtechceu.gtceu.GTCEu;
import com.gregtechceu.gtceu.api.GTValues;
import com.gregtechceu.gtceu.api.data.chemical.ChemicalHelper;
import com.gregtechceu.gtceu.api.data.tag.TagPrefix;
import com.gregtechceu.gtceu.api.machine.MultiblockMachineDefinition;
import com.gregtechceu.gtceu.api.machine.multiblock.PartAbility;
import com.gregtechceu.gtceu.api.pattern.FactoryBlockPattern;
import com.gregtechceu.gtceu.api.pattern.MultiblockShapeInfo;
import com.gregtechceu.gtceu.api.pattern.Predicates;
import com.gregtechceu.gtceu.api.pattern.util.RelativeDirection;
import com.gregtechceu.gtceu.common.data.*;

import net.minecraft.core.Direction;
import net.minecraft.network.chat.Component;
import net.minecraft.world.item.DyeColor;
import net.minecraft.world.level.block.Blocks;
import net.minecraft.world.level.block.DirectionalBlock;
import net.minecraft.world.level.material.Fluids;

import appeng.core.definitions.AEBlocks;
import earth.terrarium.adastra.common.registry.ModBlocks;

import java.util.Comparator;

import static com.gregtechceu.gtceu.api.machine.multiblock.PartAbility.*;
import static com.gregtechceu.gtceu.api.pattern.Predicates.*;
import static com.gregtechceu.gtceu.api.pattern.util.RelativeDirection.*;
import static com.gregtechceu.gtceu.common.data.GTMaterials.Aluminium;
import static org.gte.gtecore.api.GTEValues.*;
import static org.gte.gtecore.common.block.BlockMap.*;
import static org.gte.gtecore.utils.register.MachineRegisterUtils.CHEMICAL_PLANT_DISPLAY;
import static org.gte.gtecore.utils.register.MachineRegisterUtils.multiblock;

public interface MultiBlockA {

    static void init() {}

    MultiblockMachineDefinition EVAPORATION_PLANT = multiblock("evaporation_plant", "蒸发塔", ElectricMultiblockMachine::new)
            .langValue("Evaporation Tower")
            .nonYAxisRotation()
            .recipe(GTERecipeTypes.EVAPORATION_RECIPES)
            .overclock()
            .block(GTEBlocks.STAINLESS_EVAPORATION_CASING)
            .pattern(definition -> FactoryBlockPattern.start(RIGHT, BACK, UP)
                    .aisle("FYF", "YYY", "FYF")
                    .aisle("YSY", "Y#Y", "YYY")
                    .aisle("XXX", "X#X", "XXX").setRepeatable(5)
                    .aisle(" Z ", "ZZZ", " Z ")
                    .where('S', Predicates.controller(blocks(definition.getBlock())))
                    .where('Y', blocks(GTEBlocks.STAINLESS_EVAPORATION_CASING.get())
                            .or(Predicates.abilities(PartAbility.INPUT_ENERGY).setMinGlobalLimited(1)
                                    .setMaxGlobalLimited(2))
                            .or(Predicates.abilities(PartAbility.IMPORT_FLUIDS).setExactLimit(1))
                            .or(Predicates.abilities(PartAbility.EXPORT_ITEMS).setMaxGlobalLimited(1)))
                    .where('X', blocks(GTEBlocks.STAINLESS_EVAPORATION_CASING.get())
                            .or(Predicates.abilities(PartAbility.EXPORT_FLUIDS_1X).setMinLayerLimited(1)
                                    .setMaxLayerLimited(1)))
                    .where('Z', blocks(GTEBlocks.STAINLESS_EVAPORATION_CASING.get()))
                    .where('F', Predicates.frames(Aluminium))
                    .where('#', Predicates.air())
                    .where(' ', Predicates.any())
                    .build())
            .partSorter(Comparator.comparingInt(a -> a.self().getPos().getY()))
            .workableCasingRenderer(GTECore.id("block/casings/stainless_evaporation_casing"), GTCEu.id("block/multiblock/evaporation_plant"))
            .register();

    MultiblockMachineDefinition PLASMA_CONDENSER = multiblock("plasma_condenser", "等离子冷凝器", ElectricMultiblockMachine::new)
            .allRotation()
            .recipe(GTERecipeTypes.PLASMA_CONDENSER_RECIPES)
            .customTooltipsBuilder(true, false, false)
            .perfectOverclock()
            .block(GTEBlocks.ANTIFREEZE_HEATPROOF_MACHINE_CASING)
            .pattern(definition -> FactoryBlockPattern.start()
                    .aisle("       ", "       ", "  aaa  ", "  aaa  ", "  aaa  ", "       ", "       ")
                    .aisle("       ", "  aaa  ", " aaaaa ", " aabaa ", " aaaaa ", "  aaa  ", "       ")
                    .aisle("  aaa  ", " aaaaa ", "aabbbaa", "aabcbaa", "aabbbaa", " aaaaa ", "  aaa  ")
                    .aisle("  aaa  ", " aabaa ", "aabcbaa", "abcccba", "aabcbaa", " aabaa ", "  aaa  ")
                    .aisle("  aaa  ", " aaaaa ", "aabbbaa", "aabcbaa", "aabbbaa", " aaaaa ", "  aaa  ")
                    .aisle("       ", "  aaa  ", " aaaaa ", " aabaa ", " aaaaa ", "  aaa  ", "       ")
                    .aisle("       ", "       ", "  aaa  ", "  ada  ", "  aaa  ", "       ", "       ")
                    .where('a', blocks(GTEBlocks.ANTIFREEZE_HEATPROOF_MACHINE_CASING.get())
                            .setMinGlobalLimited(120)
                            .or(autoAbilities(definition.getRecipeTypes()))
                            .or(abilities(MAINTENANCE).setExactLimit(1)))
                    .where('b', blocks(GTEBlocks.AMPROSIUM_PIPE_CASING.get()))
                    .where('c', blocks(GTEBlocks.LASER_COOLING_CASING.get()))
                    .where('d', controller(blocks(definition.get())))
                    .where(' ', any())
                    .build())
            .workableCasingRenderer(GTECore.id("block/casings/antifreeze_heatproof_machine_casing"), GTCEu.id("block/multiblock/vacuum_freezer"))
            .register();

    MultiblockMachineDefinition RARE_EARTH_CENTRIFUGAL = multiblock("rare_earth_centrifugal", "稀土离心机", ElectricMultiblockMachine::new)
            .allRotation()
            .recipe(GTERecipeTypes.RARE_EARTH_CENTRIFUGAL_RECIPES)
            .parallelizableTooltips()
            .parallelizableOverclock()
            .block(GTBlocks.CASING_HSSE_STURDY)
            .pattern((definition) -> FactoryBlockPattern.start()
                    .aisle(" bbb ", "bbbbb", "bbbbb", "bbbbb", " bbb ")
                    .aisle("bbbbb", "bcccb", "bcccb", "bcccb", "bbbbb")
                    .aisle("bbbbb", "bcdcb", "bcdcb", "bcdcb", "bbbbb")
                    .aisle("bbbbb", "bcccb", "bcccb", "bcccb", "bbbbb")
                    .aisle(" bbb ", "bbbbb", "bbabb", "bbbbb", " bbb ")
                    .where('a', controller(blocks(definition.get())))
                    .where('b', blocks(GTBlocks.CASING_HSSE_STURDY.get())
                            .setMinGlobalLimited(80)
                            .or(abilities(PARALLEL_HATCH).setMaxGlobalLimited(1))
                            .or(autoAbilities(definition.getRecipeTypes()))
                            .or(abilities(MAINTENANCE).setExactLimit(1)))
                    .where('c', blocks(GTBlocks.CASING_TUNGSTENSTEEL_GEARBOX.get()))
                    .where('d', blocks(GTEBlocks.AMPROSIUM_PIPE_CASING.get()))
                    .where(' ', any())
                    .build())
            .workableCasingRenderer(GTCEu.id("block/casings/solid/machine_casing_sturdy_hsse"), GTCEu.id("block/multiblock/gcym/large_centrifuge"))
            .register();

    MultiblockMachineDefinition ADVANCED_RARE_EARTH_CENTRIFUGAL = multiblock("advanced_rare_earth_centrifugal", "进阶稀土离心机", ElectricMultiblockMachine::new)
            .nonYAxisRotation()
            .recipe(GTERecipeTypes.RARE_EARTH_CENTRIFUGAL_RECIPES)
            .parallelizableTooltips()
            .customTooltipsBuilder(true, true, false)
            .parallelizablePerfectOverclock()
            .block(GTEBlocks.SPS_CASING)
            .pattern((definition) -> FactoryBlockPattern.start(RelativeDirection.FRONT, RelativeDirection.UP, RelativeDirection.RIGHT)
                    .aisle("                        ", "                        ", "                        ", "                        ", "                        ", "                        ", "                        ", "                        ", "                        ", "                        ", "                        ", "                        ", "                        ")
                    .aisle("   AAAAAAA              ", "     B                  ", "     B                  ", "   CCCCC                ", "     B                  ", "     B                  ", "   CCCCC                ", "     B                  ", "     B                  ", "                        ", "                        ", "                        ", "                        ")
                    .aisle("  AADDDDDAA             ", "                        ", "                        ", "  C     C               ", "                        ", "                        ", "  C     C               ", "                        ", "                        ", "                        ", "                        ", "                        ", "                        ")
                    .aisle(" AADDDDDDDA             ", "  B  D  B               ", "  B  E  B               ", " CB EEE BC              ", "  B EEE B               ", "  B EEE B               ", " CB EEE BC              ", "  B EEE B               ", "  B  E  B               ", "                        ", "                        ", "                        ", "                        ")
                    .aisle("AADDDDDDDDA             ", "     D                  ", "   EEEEE                ", "C  EEEEE  C             ", "   E F E                ", "   E F E                ", "C  E F E  C             ", "   EEEEE                ", "   EEEEE                ", "                        ", "                        ", "                        ", "                        ")
                    .aisle("ADDDDDDDDDAA            ", "    DDD                 ", "   EEEEE                ", "C EEGGGEE C             ", "  E H H E               ", "  E H H E               ", "C E H H E C             ", "  EEGGGEE               ", "   EEEEE                ", "    DDD                 ", "                        ", "                        ", "                        ")
                    .aisle("ADDDDDDDDDDAAA  AAAAA   ", "B DDDDDDD B             ", "B EEEEEE  B             ", "C EEGGGEE C             ", "B EF G FE B             ", "B EF G FE B             ", "C EF G FE C             ", "B EEGGGEE B             ", "B EEEGEEE B             ", "    D D                 ", "    IAI                 ", "                        ", "                        ")
                    .aisle("ADDDDDDDDDDDDAAAADDDAA  ", "    DDD          B      ", "   EEEEE         B      ", "C EEGGGEE C    CCCCC    ", "  E H H E        B      ", "  E H H E        B      ", "C E H H E C    CCCCC    ", "  EEGGGEE        B      ", "   EEEEE         B      ", "    DAD                 ", "    IAI                 ", "                        ", "                        ")
                    .aisle("ADDDDDDDDDDDDDADDDDDDA  ", "     D                  ", "   EEEEE                ", "C  EEEEE  C   C     C   ", "   E F E                ", "   E F E                ", "C  E F E  C   C     C   ", "   EEEEE                ", "   EEEEE                ", "                        ", "    IAI                 ", "    IAI                 ", "                        ")
                    .aisle("AAADDDDDDDDDDDDDDDDDDAb ", "  B  D  B     B  D  B   ", "  B  E  B     B  E  B   ", " CB EEE BC   CB EEE BC  ", "  B EEE B     B EEE B   ", "  B EEE B     B EEE B   ", " CB EEE BC   CB EEE BC  ", "  B EEE B     B EEE B   ", "  B  E  B     B  E  B   ", "                        ", "                        ", "    IAI                 ", "                        ")
                    .aisle("  AADDDDDDDDDDDDDDDDDDb ", "                 D      ", "               EEEEE    ", "  C     C   C  EEEEE  C ", "               E F E    ", "               E F E    ", "  C     C   C  E F E  C ", "               EEEEE    ", "               EEEEE    ", "                        ", "                        ", "    IAI                 ", "                        ")
                    .aisle("   ADDDDDDDDDDDDDDDDDDAb", "     B   A      DDD   Ab", "     B   A     EEEEE  Ab", "   CCCCC A  C EEGGGEE C ", "     B   A    E H H E   ", "     B   A    E H H E   ", "   CCCCC A  C E H H E C ", "     B   A    EEGGGEE   ", "     B   A     EEEEE    ", "         A      DDD     ", "         A     III      ", "    IAAAAAIIIIII        ", "     DDDDDDDD           ")
                    .aisle("   ADDDDDDDDDDDDDDDDDDAb", "        AAA B DDDDDDD B~", "        AAA B EEEEEE  Bb", "        AAA C EEGGGEE C ", "        AAA B EF G FE B ", "        AAA B EF G FE B ", "        AAA C EF G FE C ", "        AAA B EEGGGEE B ", "        AAA B EEEGEEE B ", "        AAA     AGD     ", "        AAA    AAA      ", "    IIIIAAAAAAAA        ", "     DDDDDDDD           ")
                    .aisle("   ADDDDDDDDDDDDDDDDDDAb", "     B   A      DDD   Ab", "     B   A     EEEEE  Ab", "   CCCCC A  C EEGGGEE C ", "     B   A    E H H E   ", "     B   A    E H H E   ", "   CCCCC A  C E H H E C ", "     B   A    EEGGGEE   ", "     B   A     EEEEE    ", "         A      DDD     ", "         A     III      ", "    IAAAAAIIIIII        ", "     DDDDDDDD           ")
                    .aisle("  AADDDDDDDDDDDDDDDDDDb ", "                 D      ", "               EEEEE    ", "  C     C   C  EEEEE  C ", "               E F E    ", "               E F E    ", "  C     C   C  E F E  C ", "               EEEEE    ", "               EEEEE    ", "                        ", "                        ", "    IAI                 ", "                        ")
                    .aisle("AAADDDDDDDDDDDDDDDDDDAb ", "  B  D  B     B  D  B   ", "  B  E  B     B  E  B   ", " CB EEE BC   CB EEE BC  ", "  B EEE B     B EEE B   ", "  B EEE B     B EEE B   ", " CB EEE BC   CB EEE BC  ", "  B EEE B     B EEE B   ", "  B  E  B     B  E  B   ", "                        ", "                        ", "    IAI                 ", "                        ")
                    .aisle("ADDDDDDDDDDDDDADDDDDDA  ", "     D                  ", "   EEEEE                ", "C  EEEEE  C   C     C   ", "   E F E                ", "   E F E                ", "C  E F E  C   C     C   ", "   EEEEE                ", "   EEEEE                ", "                        ", "    IAI                 ", "    IAI                 ", "                        ")
                    .aisle("ADDDDDDDDDDDDAAAADDDAA  ", "    DDD          B      ", "   EEEEE         B      ", "C EEGGGEE C    CCCCC    ", "  E H H E        B      ", "  E H H E        B      ", "C E H H E C    CCCCC    ", "  EEGGGEE        B      ", "   EEEEE         B      ", "    DAD                 ", "    IAI                 ", "                        ", "                        ")
                    .aisle("ADDDDDDDDDDAAA  AAAAA   ", "B DDDDDDD B             ", "B EEEEEE  B             ", "C EEGGGEE C             ", "B EF G FE B             ", "B EF G FE B             ", "C EF G FE C             ", "B EEGGGEE B             ", "B EEEGEEE B             ", "    D D                 ", "    IAI                 ", "                        ", "                        ")
                    .aisle("ADDDDDDDDDAA            ", "    DDD                 ", "   EEEEE                ", "C EEGGGEE C             ", "  E H H E               ", "  E H H E               ", "C E H H E C             ", "  EEGGGEE               ", "   EEEEE                ", "    DDD                 ", "                        ", "                        ", "                        ")
                    .aisle("AADDDDDDDDA             ", "     D                  ", "   EEEEE                ", "C  EEEEE  C             ", "   E F E                ", "   E F E                ", "C  E F E  C             ", "   EEEEE                ", "   EEEEE                ", "                        ", "                        ", "                        ", "                        ")
                    .aisle(" AADDDDDDDA             ", "  B  D  B               ", "  B  E  B               ", " CB EEE BC              ", "  B EEE B               ", "  B EEE B               ", " CB EEE BC              ", "  B EEE B               ", "  B  E  B               ", "                        ", "                        ", "                        ", "                        ")
                    .aisle("  AADDDDDAA             ", "                        ", "                        ", "  C     C               ", "                        ", "                        ", "  C     C               ", "                        ", "                        ", "                        ", "                        ", "                        ", "                        ")
                    .aisle("   AAAAAAA              ", "     B                  ", "     B                  ", "   CCCCC                ", "     B                  ", "     B                  ", "   CCCCC                ", "     B                  ", "     B                  ", "                        ", "                        ", "                        ", "                        ")
                    .where('~', controller(blocks(definition.get())))
                    .where('A', blocks(GTEBlocks.SPS_CASING.get()))
                    .where('B', blocks(GTEBlocks.DEGENERATE_RHENIUM_CONSTRAINED_CASING.get()))
                    .where('C', blocks(GTEBlocks.ADVANCED_FUSION_COIL.get()))
                    .where('D', blocks(GTEBlocks.HYPER_MECHANICAL_CASING.get()))
                    .where('E', blocks(GTBlocks.CASING_HSSE_STURDY.get()))
                    .where('F', blocks(GTEBlocks.HYPER_CORE.get()))
                    .where('G', blocks(GTEBlocks.AMPROSIUM_GEARBOX.get()))
                    .where('H', blocks(GTEBlocks.AMPROSIUM_PIPE_CASING.get()))
                    .where('I', blocks(ChemicalHelper.getBlock(TagPrefix.frameGt, GTMaterials.HastelloyX)))
                    .where('b', blocks(GTEBlocks.SPS_CASING.get())
                            .or(GTEPredicates.autoLaserAbilities(definition.getRecipeTypes()))
                            .or(abilities(PARALLEL_HATCH).setMaxGlobalLimited(1))
                            .or(abilities(MAINTENANCE).setExactLimit(1)))
                    .where(' ', any())
                    .build())
            .workableCasingRenderer(GTECore.id("block/casings/sps_casing"), GTCEu.id("block/multiblock/gcym/large_centrifuge"))
            .register();

    MultiblockMachineDefinition SPS_CRAFTING = multiblock("sps_crafting", "超临界合成机", ElectricMultiblockMachine::new)
            .allRotation()
            .recipe(GTERecipeTypes.TRANSCENDING_CRAFTING_RECIPES)
            .customTooltipsBuilder(true, false, false)
            .perfectOverclock()
            .block(GTBlocks.FUSION_CASING_MK2)
            .pattern((definition) -> FactoryBlockPattern.start()
                    .aisle("bbbbbbb", "bcccccb", "bcfffcb", "bcfffcb", "bcfffcb", "bcccccb", "bbbbbbb")
                    .aisle("bcccccb", "c     c", "c     c", "c     c", "c     c", "c     c", "bcccccb")
                    .aisle("bcccccb", "c ddd c", "f ddd f", "f ddd f", "f ddd f", "c ddd c", "bcccccb")
                    .aisle("bcccccb", "c ded c", "f ded f", "f dgd f", "f ded f", "c ded c", "bcccccb")
                    .aisle("bcccccb", "c ddd c", "f ddd f", "f ddd f", "f ddd f", "c ddd c", "bcccccb")
                    .aisle("bcccccb", "c     c", "c     c", "c     c", "c     c", "c     c", "bcccccb")
                    .aisle("bbbbbbb", "bccaccb", "bcfffcb", "bcfffcb", "bcfffcb", "bcccccb", "bbbbbbb")
                    .where('a', controller(blocks(definition.get())))
                    .where('b', blocks(GTEBlocks.SPS_CASING.get()))
                    .where('c', blocks(GTBlocks.FUSION_CASING_MK2.get())
                            .setMinGlobalLimited(100)
                            .or(autoAbilities(definition.getRecipeTypes()))
                            .or(abilities(MAINTENANCE).setExactLimit(1)))
                    .where('d', blocks(Blocks.CRYING_OBSIDIAN))
                    .where('e', blocks(Blocks.REINFORCED_DEEPSLATE))
                    .where('f', blocks(GTBlocks.FUSION_GLASS.get()))
                    .where('g', blocks(GTEBlocks.MAGIC_CORE.get()))
                    .where(' ', air())
                    .build())
            .workableCasingRenderer(GTCEu.id("block/casings/fusion/fusion_casing_mk2"), GTCEu.id("block/multiblock/assembly_line"))
            .register();

    MultiblockMachineDefinition ADVANCED_SPS_CRAFTING = multiblock("advanced_sps_crafting", "进阶超临界合成机", ElectricMultiblockMachine::new)
            .nonYAxisRotation()
            .recipe(GTERecipeTypes.TRANSCENDING_CRAFTING_RECIPES)
            .parallelizableTooltips()
            .customTooltipsBuilder(true, true, false)
            .parallelizablePerfectOverclock()
            .block(GTBlocks.FUSION_CASING_MK2)
            .pattern((definition) -> FactoryBlockPattern.start(RelativeDirection.FRONT, RelativeDirection.UP, RelativeDirection.RIGHT)
                    .aisle("            AAAA AAAA           ", "            ABBA ABBA           ", "            ABBA ABBA           ", "                                ", "                                ", "                                ", "                                ", "                                ", "                                ", "                                ", "                                ", "                                ", "                                ", "                                ", "                                ", "                                ", "                                ")
                    .aisle("            AAAA AAAA           ", "            ABBA ABBA           ", "            ABBA ABBA           ", "            ABBA ABBA           ", "                                ", "                                ", "                                ", "                                ", "                                ", "                                ", "                                ", "                                ", "                                ", "                                ", "                                ", "                                ", "                                ")
                    .aisle("          CCCCCCCCCCCCC         ", "          DDDDDDDDDDDDD         ", "           CABBA ABBAC          ", "            ABBA ABBA           ", "            ABBA ABBA           ", "            CCCCCCCCC           ", "                                ", "                                ", "                                ", "                                ", "                                ", "                                ", "                                ", "                                ", "                                ", "                                ", "                                ")
                    .aisle("         CCCCCCCCCCCCCCC        ", "         DDEABBBBBBBAEDD        ", "          CEABBA ABBAEC         ", "           EABBA ABBAE          ", "           EABBA ABBAE          ", "            CBBCCCBBC           ", "                                ", "                                ", "                                ", "                                ", "                                ", "                                ", "                                ", "                                ", "                                ", "                                ", "                                ")
                    .aisle("        CCCCCCCCCCCCCCCCC       ", "        DDAAABBBBBBBAAADD       ", "         CAAABFBBBFBAAAC        ", "          AAABFBBBFBAAA         ", "           AABBBBBBBAA          ", "            CBBCCCBBC           ", "                                ", "                                ", "                                ", "                                ", "                                ", "                                ", "                                ", "                                ", "                                ", "                                ", "                                ")
                    .aisle("       CCCCCCCCCCCCCCCCCCC      ", "       DD AAABBBBBBBAAA DD      ", "        C AEFB  G  BFEA C       ", "          AGFB     BFGA         ", "          AAAB BBB BAAA         ", "             BBCCCBB            ", "                                ", "                                ", "                                ", "                                ", "                                ", "                                ", "                                ", "                                ", "                                ", "                                ", "                                ")
                    .aisle("       CCCCCCCCCCCCCCCCCCC      ", "       D  AAABBBBBBBAAA  D      ", "       C  AEFB  G  BFEA  C      ", "          AGFB     BFGA         ", "          AAABBBBBBBAAA         ", "               AAA              ", "                                ", "                                ", "                                ", "                                ", "                                ", "                                ", "                                ", "                                ", "                                ", "                                ", "                                ")
                    .aisle("      CCCCCCCCCCCCCCCCCCCCC     ", "      DD  AAABBBBBBBAAA  DD     ", "       C  AEFBBBGBBBFEA  C      ", "          AGFBBBBBBBFGA         ", "          AAA  AAA  AAA         ", "                                ", "                                ", "                                ", "                                ", "                                ", "                                ", "                                ", "                                ", "                                ", "                                ", "                                ", "                                ")
                    .aisle("      CCCCCCCCCCCCCCCCCCCCC     ", "      D   AAA  AAA  AAA   D     ", "      C   AAA  AGA  AAA   C     ", "          AGA  AAA  AGA         ", "           AA       AA          ", "                                ", "                                ", "                                ", "                                ", "                                ", "                                ", "                                ", "                                ", "                                ", "                                ", "                                ", "                                ")
                    .aisle("     CCCCCCCCCCCCCCCCCCCCCCC    ", "     DD                   DD    ", "      C         G         C     ", "           G    G    G          ", "                G               ", "                                ", "                                ", "                                ", "                                ", "                                ", "                                ", "                                ", "                                ", "                                ", "                                ", "                                ", "                                ")
                    .aisle("     CCCCCCCCCCCCCCCCCCCCCCC    ", "     D AAA             AAA D    ", "     C AAA             AAA C    ", "       HHH G         G HHH      ", "       HHH      G      HHH      ", "       AAA             AAA      ", "                                ", "                                ", "                                ", "                                ", "                                ", "                                ", "                                ", "                                ", "                                ", "                                ", "                                ")
                    .aisle("    CCCCCCCCCCCCCCCCCCCCCCCCC   ", "    DDAAAAA           AAAAADD   ", "     CAFEFIIIIIIIIIIIIIFEFAC    ", "      HF FHG         GHF FH     ", "      HFEFH     G     HFEFH     ", "      AAAAA           AAAAA     ", "                                ", "                                ", "                                ", "                                ", "                                ", "                                ", "                                ", "                                ", "                                ", "                                ", "                                ")
                    .aisle("    CCCCCCCCCCCCCCCCCCCCCCCCC   ", "    D AAAAA           AAAAA D   ", "    C AEEEA  I     I  AEEEA C   ", "      H J HG         GH J H     ", "      HEEEH     G     HEEEH     ", "      AAEAA           AAEAA     ", "                                ", "                                ", "                                ", "                                ", "                                ", "                                ", "                                ", "                                ", "                                ", "                                ", "                                ")
                    .aisle("    CCCCCCCCCCCCCCCCCCCCCCCCC   ", "    D AAAAA    C C    AAAAA D   ", "    C AFEFIIII C C IIIIFEFA C   ", "      HF FHG   C C   GHF FH     ", "      HFEFH    CGC    HFEFH     ", "      AAAAA    C C    AAAAA     ", "               C C              ", "                                ", "                                ", "                                ", "                                ", "                                ", "                                ", "                                ", "                                ", "                                ", "                                ")
                    .aisle("   CCCCCCCCCCCCCCCCCCCCCCCCCCC  ", "   DD  AAA   KKKEKKK   AAA  DD  ", "    C  AAA   BBBBBBB   AAA  C   ", "       HHH G BHBBBHB G HHH      ", "       HHH   BHBGBHB   HHH      ", "       AAA   BBBBBBB   AAA      ", "             KKKKKKK            ", "               CBC              ", "                B               ", "                                ", "                                ", "                                ", "                                ", "                                ", "                                ", "                                ", "                                ")
                    .aisle("   CCCCCCCCCCCCCCCCCCCCCCCCCCC  ", "   D        KAAAEAAAK        D  ", "   C        BB     BB        C  ", "           GBB     BBG          ", "            BB     BB           ", "            BB     BB           ", "            KK  E  KK           ", "             BBBBBBB            ", "              BBBBB             ", "              HHBHH             ", "              HHBHH             ", "              HHBHH             ", "              HHBHH             ", "              BBBBB             ", "                E               ", "                                ", "                                ")
                    .aisle("   CCCCCCCCCCCCCCCCCCCCCCCCCCC  ", "   D       KAAAAEAAAAK       D  ", "   C       BB       BB       C  ", "           GB       BG          ", "           BB       BB          ", "           BB       BB          ", "           KK   E   KK          ", "            BB     BB           ", "             BB   BB            ", "             HH   HH            ", "             HH   HH            ", "             HH   HH            ", "             HH   HH            ", "             BB B BB            ", "              BBBBB             ", "                E               ", "                                ")
                    .aisle("  CCCCCCCCCCCCCCCCCCCCCCCCCCCCC ", "  DD      KAAAAAEAAAAAK      DD ", "   C      BB         BB      C  ", "          BG         GB         ", "          BB         BB         ", "          BB         BB         ", "          KK    E    KK         ", "           BB       BB          ", "            BB     BB           ", "            HH LLL HH           ", "            HH  L  HH           ", "            HH  L  HH           ", "            HH LLL HH           ", "            BB     BB           ", "             BBBBBBB            ", "              AAEAA             ", "                                ")
                    .aisle(" ACCCCCCCCCCCCCCCCCCCCCCCCCCCCCA", " ADAAAACC KAAAAAEAAAAAK CCAAAADA", " AAAAAAAAAB   F   F   BAAAAAAAAA", "       AAAB   FFFFF   BAAA      ", "        AAB   F   F   BAA       ", "        AAB   FFFFF   BAA       ", "         AK   F E F   KA        ", "         AAB  FFFFF  BAA        ", "           BB       BB          ", "           HH L L L HH          ", "           HH       HH          ", "           HH       HH          ", "           HH L L L HH          ", "           BB       BB          ", "            BB     BB           ", "             AAAKAAA            ", "                                ")
                    .aisle("  MCCCCCCCCCCCCCCCCCCCCCCCCCCCMA", "  MMMMMMM KAAAAAEAAAAAK MMMMMMMA", " ACCCCCCC B           B CCCCCCCA", "   AAAANN B   F   F   B NNAAAA  ", "       NN B           B NN      ", "        N B   F   F   B N       ", "        NAK     E     KAN       ", "        NAAB  F   F  BAAN       ", "         AAB         BAA        ", "           H L  L  L H          ", "           H         H          ", "           H         H          ", "           H L  L  L H          ", "           B         B          ", "            BB     BB           ", "             AAEKEAA            ", "               AAA              ")
                    .aisle("  MCCCCCCCCCCCCCCCCCCCCCCCCCCCMA", "  MMMMMMM EEEEEEJEEEEEE MMMMMMM~", " ACCCCCCC B     J     B CCCCCCCA", "  AAEEENN B   F J F   B NNEEEAA ", "       NN B     J     B NN      ", "       NN B   F J F   B NN      ", "       NNAEEEEEEJEEEEEEANN      ", "        NABB  F J F  BBAN       ", "        NABB    J    BBAN       ", "           B LLLJLLL B          ", "           B L  J  L B          ", "           B L  J  L B          ", "           B LLLJLLL B          ", "           BB   J   BB          ", "           EBB  K  BBE          ", "            EEKKKKKEE           ", "               AAA              ")
                    .aisle("  MCCCCCCCCCCCCCCCCCCCCCCCCCCCMA", "  MMMMMMM KAAAAAEAAAAAK MMMMMMMA", " ACCCCCCC B           B CCCCCCCA", "   AAAANN B   F   F   B NNAAAA  ", "       NN B           B NN      ", "        N B   F   F   B N       ", "        NAK     E     KAN       ", "        NAAB  F   F  BAAN       ", "         AAB         BAA        ", "           H L  L  L H          ", "           H         H          ", "           H         H          ", "           H L  L  L H          ", "           B         B          ", "            BB     BB           ", "             AAEKEAA            ", "               AAA              ")
                    .aisle(" ACCCCCCCCCCCCCCCCCCCCCCCCCCCCCA", " ADAAAACC KAAAAAEAAAAAK CCAAAADA", " AAAAAAAAAB   F   F   BAAAAAAAAA", "       AAAB   FFFFF   BAAA      ", "        AAB   F   F   BAA       ", "        AAB   FFFFF   BAA       ", "         AK   F E F   KA        ", "         AAB  FFFFF  BAA        ", "           BB       BB          ", "           HH L L L HH          ", "           HH       HH          ", "           HH       HH          ", "           HH L L L HH          ", "           BB       BB          ", "            BB     BB           ", "             AAAKAAA            ", "                                ")
                    .aisle("  CCCCCCCCCCCCCCCCCCCCCCCCCCCCC ", "  DD      KAAAAAEAAAAAK      DD ", "   C      BB         BB      C  ", "          BG         GB         ", "          BB         BB         ", "          BB         BB         ", "          KK    E    KK         ", "           BB       BB          ", "            BB     BB           ", "            HH LLL HH           ", "            HH  L  HH           ", "            HH  L  HH           ", "            HH LLL HH           ", "            BB     BB           ", "             BBBBBBB            ", "              AAEAA             ", "                                ")
                    .aisle("   CCCCCCCCCCCCCCCCCCCCCCCCCCC  ", "   D       KAAAAEAAAAK       D  ", "   C       BB       BB       C  ", "           GB       BG          ", "           BB       BB          ", "           BB       BB          ", "           KK   E   KK          ", "            BB     BB           ", "             BB   BB            ", "             HH   HH            ", "             HH   HH            ", "             HH   HH            ", "             HH   HH            ", "             BB B BB            ", "              BBBBB             ", "                E               ", "                                ")
                    .aisle("   CCCCCCCCCCCCCCCCCCCCCCCCCCC  ", "   D        KAAAEAAAK        D  ", "   C        BB     BB        C  ", "           GBB     BBG          ", "            BB     BB           ", "            BB     BB           ", "            KK  E  KK           ", "             BBBBBBB            ", "              BBBBB             ", "              HHBHH             ", "              HHBHH             ", "              HHBHH             ", "              HHBHH             ", "              BBBBB             ", "                E               ", "                                ", "                                ")
                    .aisle("   CCCCCCCCCCCCCCCCCCCCCCCCCCC  ", "   DD  AAA   KKKEKKK   AAA  DD  ", "    C  AAA   BBBBBBB   AAA  C   ", "       HHH G BHBBBHB G HHH      ", "       HHH   BHBBBHB   HHH      ", "       AAA   BBBBBBB   AAA      ", "             KKKKKKK            ", "               CBC              ", "                B               ", "                                ", "                                ", "                                ", "                                ", "                                ", "                                ", "                                ", "                                ")
                    .aisle("    CCCCCCCCCCCCCCCCCCCCCCCCC   ", "    D AAAAA    C C    AAAAA D   ", "    C AFEFIIII C C IIIIFEFA C   ", "      HF FHG   C C   GHF FH     ", "      HFEFH    CGC    HFEFH     ", "      AAAAA    C C    AAAAA     ", "               C C              ", "                                ", "                                ", "                                ", "                                ", "                                ", "                                ", "                                ", "                                ", "                                ", "                                ")
                    .aisle("    CCCCCCCCCCCCCCCCCCCCCCCCC   ", "    D AAAAA           AAAAA D   ", "    C AEEEA  I     I  AEEEA C   ", "      H J HG         GH J H     ", "      HEEEH     G     HEEEH     ", "      AAEAA           AAEAA     ", "                                ", "                                ", "                                ", "                                ", "                                ", "                                ", "                                ", "                                ", "                                ", "                                ", "                                ")
                    .aisle("    CCCCCCCCCCCCCCCCCCCCCCCCC   ", "    DDAAAAA           AAAAADD   ", "     CAFEFAIIIIIIIIIIIIFEFAC    ", "      HF FHG         GHF FH     ", "      HFEFH     G     HFEFH     ", "      AAAAA           AAAAA     ", "                                ", "                                ", "                                ", "                                ", "                                ", "                                ", "                                ", "                                ", "                                ", "                                ", "                                ")
                    .aisle("     CCCCCCCCCCCCCCCCCCCCCCC    ", "     D AAA             AAA D    ", "     C AAA             AAA C    ", "       HHH G         G HHH      ", "       HHH      G      HHH      ", "       AAA             AAA      ", "                                ", "                                ", "                                ", "                                ", "                                ", "                                ", "                                ", "                                ", "                                ", "                                ", "                                ")
                    .aisle("     CCCCCCCCCCCCCCCCCCCCCCC    ", "     DD                   DD    ", "      C         G         C     ", "           G    G    G          ", "                G               ", "                                ", "                                ", "                                ", "                                ", "                                ", "                                ", "                                ", "                                ", "                                ", "                                ", "                                ", "                                ")
                    .aisle("      CCCCCCCCCCCCCCCCCCCCC     ", "      D   AAA  AAA  AAA   D     ", "      C   AAA  AGA  AAA   C     ", "          AGA  AAA  AGA         ", "           AA       AA          ", "                                ", "                                ", "                                ", "                                ", "                                ", "                                ", "                                ", "                                ", "                                ", "                                ", "                                ", "                                ")
                    .aisle("      CCCCCCCCCCCCCCCCCCCCC     ", "      DD  AAABBBBBBBAAA  DD     ", "       C  AEFBBBGBBBFEA  C      ", "          AGFBBBBBBBFGA         ", "          AAA  AAA  AAA         ", "                                ", "                                ", "                                ", "                                ", "                                ", "                                ", "                                ", "                                ", "                                ", "                                ", "                                ", "                                ")
                    .aisle("       CCCCCCCCCCCCCCCCCCC      ", "       D  AAABBBBBBBAAA  D      ", "       C  AEFB  G  BFEA  C      ", "          AGFB     BFGA         ", "          AAABBBBBBBAAA         ", "               AAA              ", "                                ", "                                ", "                                ", "                                ", "                                ", "                                ", "                                ", "                                ", "                                ", "                                ", "                                ")
                    .aisle("       CCCCCCCCCCCCCCCCCCC      ", "       DD AAABBBBBBBAAA DD      ", "        C AEFB  G  BFEA C       ", "          AGFB     BFGA         ", "          AAAB BBB BAAA         ", "             BBCCCBB            ", "                                ", "                                ", "                                ", "                                ", "                                ", "                                ", "                                ", "                                ", "                                ", "                                ", "                                ")
                    .aisle("        CCCCCCCCCCCCCCCCC       ", "        DDAAABBBBBBBAAADD       ", "         CAAABFBBBFBAAAC        ", "          AAABFBBBFBAAA         ", "           AABBBBBBBAA          ", "            CBBCCCBBC           ", "                                ", "                                ", "                                ", "                                ", "                                ", "                                ", "                                ", "                                ", "                                ", "                                ", "                                ")
                    .aisle("         CCCCCCCCCCCCCCC        ", "         DDEABBBBBBBAEDD        ", "          CEABBA ABBAEC         ", "           EABBA ABBAE          ", "           EABBA ABBAE          ", "            CBBCCCBBC           ", "                                ", "                                ", "                                ", "                                ", "                                ", "                                ", "                                ", "                                ", "                                ", "                                ", "                                ")
                    .aisle("          CCCCCCCCCCCCC         ", "          DDDDDDDDDDDDD         ", "           CABBA ABBAC          ", "            ABBA ABBA           ", "            ABBA ABBA           ", "            CCCCCCCCC           ", "                                ", "                                ", "                                ", "                                ", "                                ", "                                ", "                                ", "                                ", "                                ", "                                ", "                                ")
                    .aisle("            AAAA AAAA           ", "            ABBA ABBA           ", "            ABBA ABBA           ", "            ABBA ABBA           ", "                                ", "                                ", "                                ", "                                ", "                                ", "                                ", "                                ", "                                ", "                                ", "                                ", "                                ", "                                ", "                                ")
                    .aisle("            AAAA AAAA           ", "            ABBA ABBA           ", "            ABBA ABBA           ", "                                ", "                                ", "                                ", "                                ", "                                ", "                                ", "                                ", "                                ", "                                ", "                                ", "                                ", "                                ", "                                ", "                                ")
                    .where('~', controller(blocks(definition.get())))
                    .where('A', blocks(GTEBlocks.SPS_CASING.get())
                            .setMinGlobalLimited(800)
                            .or(GTEPredicates.autoLaserAbilities(definition.getRecipeTypes()))
                            .or(abilities(PARALLEL_HATCH).setMaxGlobalLimited(1))
                            .or(abilities(MAINTENANCE).setExactLimit(1)))
                    .where('B', blocks(GTEBlocks.FUSION_CASING_MK4.get()))
                    .where('C', blocks(GTEBlocks.HYPER_MECHANICAL_CASING.get()))
                    .where('D', blocks(GTEBlocks.IRIDIUM_CASING.get()))
                    .where('E', blocks(GTEBlocks.AMPROSIUM_ACTIVE_CASING.get()))
                    .where('F', blocks(Blocks.CRYING_OBSIDIAN))
                    .where('G', blocks(GTEBlocks.ACCELERATED_PIPELINE.get()))
                    .where('H', blocks(GTBlocks.FUSION_GLASS.get()))
                    .where('I', blocks(GCYMBlocks.MOLYBDENUM_DISILICIDE_COIL_BLOCK.get()))
                    .where('J', blocks(GTEBlocks.MAGIC_CORE.get()))
                    .where('K', blocks(GTEBlocks.AMPROSIUM_CASING.get()))
                    .where('L', blocks(GTEBlocks.FUSION_COIL_MK2.get()))
                    .where('M', blocks(GTEBlocks.AMPROSIUM_PIPE_CASING.get()))
                    .where('N', blocks(GTEBlocks.HIGH_PRESSURE_RESISTANT_CASING.get()))
                    .where(' ', any())
                    .build())
            .workableCasingRenderer(GTCEu.id("block/casings/fusion/fusion_casing_mk2"), GTCEu.id("block/multiblock/assembly_line"))
            .register();

    MultiblockMachineDefinition MATTER_FABRICATOR = multiblock("matter_fabricator", "物质生成机", ElectricMultiblockMachine::new)
            .allRotation()
            .recipe(GTERecipeTypes.MATTER_FABRICATOR_RECIPES)
            .parallelizableTooltips()
            .customTooltipsBuilder(false, true, false)
            .parallelizableOverclock()
            .block(GTBlocks.HIGH_POWER_CASING)
            .pattern((definition) -> FactoryBlockPattern.start()
                    .aisle(" CCCCDDDDDCCCC ", "EFFFFDGGGDFFFFE", "EFFFFDHHHDFFFFE", "EFFFFDGGGDFFFFE", " CCCCDDDDDCCCC ")
                    .aisle("EFFFFDGGGDFFFFE", "F I IIIIIII I F", "F I I     I I F", "F I IIIIIII I F", "EFFFFDGGGDFFFFE")
                    .aisle("EFFFFDHHHDFFFFE", "F I I     I I F", "FJJJJJJJJJJJJJF", "F I I     I I F", "EFFFFDHHHDFFFFE")
                    .aisle("EFFFFDGGGDFFFFE", "F I IIIIIII I F", "F I I     I I F", "F I IIIIIII I F", "EFFFFDGGGDFFFFE")
                    .aisle(" CCCCDDDDDCCCC ", "EFFFFDGGGDFFFFE", "EFFFFDHHHDFFFFE", "EFFFFDGGGDFFFFE", " CCCCDDDDDCCCC ")
                    .aisle("               ", "   AAA   AAA   ", "   ABA   AAA   ", "   AAA   AAA   ", "               ")
                    .where('B', controller(blocks(definition.get())))
                    .where('C', blocks(ChemicalHelper.getBlock(TagPrefix.frameGt, GTMaterials.Naquadria)))
                    .where('D', blocks(GTBlocks.MACHINE_CASING_UHV.get()))
                    .where('E', blocks(GTEBlocks.NAQUADAH_ALLOY_CASING.get()))
                    .where('F', blocks(GTBlocks.HIGH_POWER_CASING.get()))
                    .where('G', blocks(GTBlocks.FILTER_CASING.get()))
                    .where('H', blocks(GCYMBlocks.ELECTROLYTIC_CELL.get()))
                    .where('I', blocks(GTBlocks.SUPERCONDUCTING_COIL.get()))
                    .where('J', blocks(GTEBlocks.AMPROSIUM_PIPE_CASING.get()))
                    .where('A', blocks(GTBlocks.HIGH_POWER_CASING.get())
                            .or(GTEPredicates.autoLaserAbilities(definition.getRecipeTypes()))
                            .or(abilities(PARALLEL_HATCH).setMaxGlobalLimited(1))
                            .or(abilities(MAINTENANCE).setExactLimit(1)))
                    .where(' ', any())
                    .build())
            .workableCasingRenderer(GTCEu.id("block/casings/hpca/high_power_casing"), GTCEu.id("block/multiblock/fusion_reactor"))
            .register();

    MultiblockMachineDefinition VOID_FLUID_DRILLING_RIG = multiblock("void_fluid_drilling_rig", "虚空流体钻机", VoidFluidDrillingRigMachine::new)
            .nonYAxisRotation()
            .tooltipsText("Requires a minimum power of 30,720EU/t", "需要最低30720EU/t的功率")
            .tooltipsText("Outputs fluids based on the dimension and circuit value", "按维度和电路值输出流体")
            .recipe(GTERecipeTypes.DUMMY_RECIPES)
            .alwaysTryModifyRecipe(true)
            .block(GTBlocks.CASING_HSSE_STURDY)
            .pattern((definition) -> FactoryBlockPattern.start(RelativeDirection.BACK, RelativeDirection.UP, RelativeDirection.LEFT)
                    .aisle("ABBBBA ", "AAAAAA ", " C C   ", " C C   ", " C C   ", " C C   ", "       ", "       ")
                    .aisle("B   BBB", "A   DDD", "    DDD", "    DDD", " C CDDD", " EEE   ", "       ", "       ")
                    .aisle("B FGBBB", "H IGDDD", "  IGD D", "  IGD D", "  IGD D", " EIEDDD", "  I    ", "  I    ")
                    .aisle("B   BBB", "A   DDD", "    DDD", "    DDD", " C CDDD", " EEE   ", "       ", "       ")
                    .aisle("ABBBBA ", "AAAAAA ", " C C   ", " C C   ", " C C   ", " C C   ", "       ", "       ")
                    .where('B', blocks(GTEBlocks.COBALT_OXIDE_CERAMIC_STRONG_THERMALLY_CONDUCTIVE_MECHANICAL_BLOCK.get()))
                    .where('C', blocks(GTBlocks.CASING_HSSE_STURDY.get()))
                    .where('D', blocks(GTBlocks.CASING_STAINLESS_CLEAN.get()))
                    .where('E', blocks(ChemicalHelper.getBlock(TagPrefix.frameGt, GTMaterials.HSSG)))
                    .where('F', blocks(GTBlocks.CASING_TUNGSTENSTEEL_GEARBOX.get()))
                    .where('G', blocks(GTBlocks.CASING_TUNGSTENSTEEL_PIPE.get()))
                    .where('H', controller(blocks(definition.get())))
                    .where('I', blocks(GTBlocks.CASING_TUNGSTENSTEEL_ROBUST.get()))
                    .where('A', blocks(GTBlocks.CASING_HSSE_STURDY.get())
                            .or(abilities(INPUT_ENERGY).setMaxGlobalLimited(2).setMinGlobalLimited(1))
                            .or(abilities(GTEPartAbility.ITEMS_INPUT).setExactLimit(1))
                            .or(abilities(EXPORT_FLUIDS).setExactLimit(1))
                            .or(abilities(MAINTENANCE).setExactLimit(1)))
                    .where(' ', any())
                    .build())
            .workableCasingRenderer(GTCEu.id("block/casings/solid/machine_casing_sturdy_hsse"), GTCEu.id("block/multiblock/fluid_drilling_rig"))
            .register();

    MultiblockMachineDefinition VOID_MINER = multiblock("void_miner", "虚空采矿机", VoidMinerMachine::new)
            .nonYAxisRotation()
            .tooltipsText("Requires 1B drilling fluid and a minimum power of 1920EU/t", "需要输入1B钻井液和最低1920EU/t的功率")
            .tooltipsText("Randomly selects 4 types of ores output based on the dimension, with the voltage level determining the maximum output quantity and the current determining the parallels", "按维度随机选取4分矿石输出，电压等级决定最大输出数量，电流决定并行数")
            .recipe(GTERecipeTypes.DUMMY_RECIPES)
            .alwaysTryModifyRecipe(true)
            .block(GTBlocks.CASING_TUNGSTENSTEEL_ROBUST)
            .pattern((definition) -> FactoryBlockPattern.start(RelativeDirection.FRONT, RelativeDirection.UP, RelativeDirection.RIGHT)
                    .aisle(" AAAAA ", " BBBBB ", "  C C  ", "  C C  ", "  CCC  ", "       ")
                    .aisle("AAA AAA", "BCD DCB", "B DED B", "B D D B", " CD DC ", "  C C  ")
                    .aisle("AA   AA", "B  F  B", "  FEF  ", "   F   ", "       ", "  C C  ")
                    .aisle("AA   AA", "B     G", "   E   ", "       ", "       ", "  C C  ")
                    .aisle("AA   AA", "B  F  B", "  FEF  ", "   F   ", "       ", "  C C  ")
                    .aisle("AAA AAA", "BCD DCB", "B DED B", "B D D B", " CD DC ", "  C C  ")
                    .aisle(" AAAAA ", " BBBBB ", "  C C  ", "  C C  ", "  CCC  ", "       ")
                    .where('A', blocks(GTEBlocks.TITANIUM_NITRIDE_CERAMIC_IMPACT_RESISTANT_MECHANICAL_BLOCK.get()))
                    .where('C', blocks(GTBlocks.CASING_TUNGSTENSTEEL_ROBUST.get()))
                    .where('D', blocks(ChemicalHelper.getBlock(TagPrefix.frameGt, GTMaterials.StainlessSteel)))
                    .where('E', blocks(GTBlocks.MACHINE_CASING_HV.get()))
                    .where('F', blocks(GTBlocks.CASING_STAINLESS_STEEL_GEARBOX.get()))
                    .where('G', controller(blocks(definition.get())))
                    .where('B', blocks(GTBlocks.CASING_TUNGSTENSTEEL_ROBUST.get())
                            .or(abilities(INPUT_ENERGY).setMaxGlobalLimited(2).setMinGlobalLimited(1))
                            .or(abilities(IMPORT_FLUIDS).setExactLimit(1))
                            .or(abilities(EXPORT_ITEMS).setExactLimit(1))
                            .or(abilities(MAINTENANCE).setExactLimit(1)))
                    .where(' ', any())
                    .build())
            .workableCasingRenderer(GTCEu.id("block/casings/solid/machine_casing_robust_tungstensteel"), GTCEu.id("block/multiblock/large_miner"))
            .register();

    MultiblockMachineDefinition LARGE_VOID_MINER = multiblock("large_void_miner", "大型虚空采矿厂", ElectricMultiblockMachine::new)
            .nonYAxisRotation()
            .recipe(GTERecipeTypes.LARGE_VOID_MINER_RECIPES)
            .recipe(GTERecipeTypes.RANDOM_ORE_RECIPES)
            .tooltipsText("Precision mode consumes resources to collect specified veins", "精准模式消耗精华采集指定矿脉")
            .tooltipsText("Random mode consumes 10KB of drilling fluid and has a longer Duration to randomly collect all ores; ensure enough output space in random mode", "随机模式消耗10KB的钻井液和更长的耗时随机采集所有矿石，随机模式注意输出空间要足够")
            .recipeModifier((machine, recipe) -> {
                if (((ElectricMultiblockMachine) machine).getRecipeType() == GTERecipeTypes.RANDOM_ORE_RECIPES) {
                    return GTERecipeModifiers.overclocking(machine, GTERecipeModifiers.accurateParallel(machine, recipe, 1 << ((((ElectricMultiblockMachine) machine).getTier() - GTValues.ZPM) << 1)));
                }
                return GTERecipeModifiers.overclocking(machine, recipe);
            })
            .block(GTBlocks.CASING_TUNGSTENSTEEL_ROBUST)
            .pattern((definition) -> FactoryBlockPattern.start()
                    .aisle("bbbbbbbbb", "bbbbbbbbb", "b       b", "b       b", "b       b", "bbbbbbbbb", "bcccccccb", "bcccccccb", "b       b", "b       b")
                    .aisle("b       b", "b       b", "         ", "         ", "         ", "b   d   b", "c  ddd  c", "c  ddd  c", "   ddd   ", "         ")
                    .aisle("b       b", "b       b", "         ", "    d    ", "   ddd   ", "b  ddd  b", "c dd dd c", "c d   d c", "  d   d  ", "         ")
                    .aisle("b   d   b", "b   d   b", "   ddd   ", "   d d   ", "  dd dd  ", "b d   d b", "cdd   ddc", "cd     dc", " d     d ", "         ")
                    .aisle("b  d d  b", "b  d d  b", "   d d   ", "  d   d  ", "  d   d  ", "bdd   ddb", "cd     dc", "cd     dc", " d     d ", "         ")
                    .aisle("b   d   b", "b   d   b", "   ddd   ", "   d d   ", "  dd dd  ", "b d   d b", "cdd   ddc", "cd     dc", " d     d ", "         ")
                    .aisle("b       b", "b       b", "         ", "    d    ", "   ddd   ", "b  ddd  b", "c dd dd c", "c d   d c", "  d   d  ", "         ")
                    .aisle("b       b", "b       b", "         ", "         ", "         ", "b   d   b", "c  ddd  c", "c  ddd  c", "   ddd   ", "         ")
                    .aisle("bbbbbbbbb", "bbbbabbbb", "b       b", "b       b", "b       b", "bbbbbbbbb", "bcccccccb", "bcccccccb", "b       b", "b       b")
                    .where('a', controller(blocks(definition.get())))
                    .where('b', blocks(GTBlocks.CASING_TUNGSTENSTEEL_ROBUST.get())
                            .setMinGlobalLimited(110)
                            .or(autoAbilities(definition.getRecipeTypes()))
                            .or(abilities(MAINTENANCE).setExactLimit(1)))
                    .where('c', blocks(ChemicalHelper.getBlock(TagPrefix.frameGt, GTMaterials.Ultimet)))
                    .where('d', blocks(GTBlocks.CASING_TITANIUM_STABLE.get()))
                    .where(' ', any())
                    .build())
            .workableCasingRenderer(GTCEu.id("block/casings/solid/machine_casing_robust_tungstensteel"), GTCEu.id("block/multiblock/large_miner"))
            .register();

    MultiblockMachineDefinition CHEMICAL_PLANT = multiblock("chemical_plant", "化工厂", CoilMultiblockMachine.createCoilMachine(false, false))
            .allRotation()
            .recipe(GTERecipeTypes.CHEMICAL)
            .tooltipsText("Coil tier above Bronze reduction energy consumption and duration by 5%", "线圈等级每高出白铜一级能耗与时间减少5%")
            .parallelizableTooltips()
            .customTooltipsBuilder(true, false, false)
            .recipeModifier(GTERecipeModifiers.coilReductionOverclock(true))
            .block(GTBlocks.CASING_PTFE_INERT)
            .pattern((definition) -> FactoryBlockPattern.start()
                    .aisle("b   b", "bbbbb", "b   b", "bbbbb", "b   b")
                    .aisle("bbbbb", "bcccb", "bdddb", "bcccb", "bbbbb")
                    .aisle("b   b", "bdddb", "bcccb", "bdddb", "b   b")
                    .aisle("bbbbb", "bcccb", "bdddb", "bcccb", "bbbbb")
                    .aisle("b   b", "abbbb", "b   b", "bbbbb", "b   b")
                    .where('a', controller(blocks(definition.get())))
                    .where('b', blocks(GTBlocks.CASING_PTFE_INERT.get())
                            .setMinGlobalLimited(60)
                            .or(blocks(GTEMachines.CATALYST_HATCH.getBlock()).setMaxGlobalLimited(1))
                            .or(abilities(PARALLEL_HATCH).setMaxGlobalLimited(1))
                            .or(GTEPredicates.autoAccelerateAbilities(definition.getRecipeTypes()))
                            .or(abilities(MAINTENANCE).setExactLimit(1)))
                    .where('c', heatingCoils())
                    .where('d', blocks(GTBlocks.CASING_POLYTETRAFLUOROETHYLENE_PIPE.get()))
                    .where(' ', any())
                    .build())
            .additionalDisplay(CHEMICAL_PLANT_DISPLAY)
            .workableCasingRenderer(GTCEu.id("block/casings/solid/machine_casing_inert_ptfe"), GTCEu.id("block/machines/chemical_reactor"))
            .register();

    MultiblockMachineDefinition DECAY_HASTENER = multiblock("decay_hastener", "衰变加速器", ElectricMultiblockMachine::new)
            .allRotation()
            .recipe(GTERecipeTypes.DECAY_HASTENER_RECIPES)
            .parallelizableTooltips()
            .parallelizableOverclock()
            .block(GTEBlocks.HYPER_MECHANICAL_CASING)
            .pattern((definition) -> FactoryBlockPattern.start()
                    .aisle("AAAAA", "ABBBA", "ADDDA", "AEEEA", "AFFFA", "AEEEA", "ADDDA", "AEEEA", "AFFFA", "AEEEA", "ADDDA", "ABBBA", "AAAAA")
                    .aisle("A   A", "BEEEB", "DGGGD", "EGGGE", "FGGGF", "EGGGE", "DGGGD", "EGGGE", "FGGGF", "EGGGE", "DGGGD", "BEEEB", "A   A")
                    .aisle("A   A", "BEEEB", "DGHGD", "EGHGE", "FGHGF", "EGHGE", "DGHGD", "EGHGE", "FGHGF", "EGHGE", "DGHGD", "BEEEB", "A   A")
                    .aisle("A   A", "BEEEB", "DGGGD", "EGGGE", "FGGGF", "EGGGE", "DGGGD", "EGGGE", "FGGGF", "EGGGE", "DGGGD", "BEEEB", "A   A")
                    .aisle("AAAAA", "ABCBA", "ADDDA", "AEEEA", "AFFFA", "AEEEA", "ADDDA", "AEEEA", "AFFFA", "AEEEA", "ADDDA", "ABBBA", "AAAAA")
                    .where('A', blocks(GTEBlocks.FISSION_REACTOR_CASING.get()))
                    .where('C', controller(blocks(definition.get())))
                    .where('D', blocks(GTBlocks.SUPERCONDUCTING_COIL.get()))
                    .where('E', blocks(GTEBlocks.HYPER_MECHANICAL_CASING.get()))
                    .where('F', blocks(ChemicalHelper.getBlock(TagPrefix.frameGt, GTMaterials.BlackSteel)))
                    .where('G', blocks(GTBlocks.FUSION_CASING.get()))
                    .where('H', blocks(GTBlocks.HERMETIC_CASING_UV.get()))
                    .where('B', blocks(GTEBlocks.HYPER_MECHANICAL_CASING.get())
                            .or(abilities(PARALLEL_HATCH).setMaxGlobalLimited(1))
                            .or(autoAbilities(definition.getRecipeTypes()))
                            .or(abilities(MAINTENANCE).setExactLimit(1)))
                    .where(' ', any())
                    .build())
            .workableCasingRenderer(GTECore.id("block/casings/hyper_mechanical_casing"), GTCEu.id("block/multiblock/data_bank"))
            .register();

    MultiblockMachineDefinition RECYCLER = multiblock("recycler", "回收机", CustomParallelMultiblockMachine.createParallel(m -> 1 << Math.max(0, (2 * (m.getTier() - 4))), true))
            .allRotation()
            .recipe(GTERecipeTypes.RECYCLER_RECIPES)
            .tooltipsText("Maximum parallelism x4 for every voltage tier above EV1", "电压等级每高出EV1级，最大并行数x4")
            .overclock()
            .block(GTBlocks.STEEL_HULL)
            .pattern((definition) -> FactoryBlockPattern.start(RelativeDirection.RIGHT, RelativeDirection.UP, RelativeDirection.BACK)
                    .aisle("DDDDD", "DDGDD", "EEEEE", "EEEEE")
                    .aisle("DEEED", "D   D", "E   E", "EFFFE")
                    .aisle("DEEED", "D   D", "EEEEE", "EEEEE")
                    .aisle("AAAAA", "ACCCA", "AAAAA", "CAAAC")
                    .aisle("AAAAA", "B   B", "A   A", "CAAAC")
                    .aisle("AAAAA", "B   B", "A   A", "CAAAC")
                    .aisle("AAAAA", "B   B", "A   A", "CAAAC")
                    .aisle("AAAAA", "ABBBA", "AAAAA", "     ")
                    .where('A', blocks(GTBlocks.CASING_STEEL_SOLID.get()))
                    .where('B', blocks(GTBlocks.FIREBOX_STEEL.get()))
                    .where('C', blocks(ChemicalHelper.getBlock(TagPrefix.frameGt, GTMaterials.StainlessSteel)))
                    .where('E', blocks(GTBlocks.STEEL_HULL.get()))
                    .where('F', blocks(GTBlocks.CASING_GRATE.get()))
                    .where('G', controller(blocks(definition.get())))
                    .where('D', blocks(GTBlocks.STEEL_HULL.get())
                            .or(autoAbilities(definition.getRecipeTypes()))
                            .or(abilities(MAINTENANCE).setExactLimit(1)))
                    .where(' ', any())
                    .build())
            .workableCasingRenderer(GTCEu.id("block/casings/steam/steel/side"), GTCEu.id("block/multiblock/gcym/large_maceration_tower"))
            .afterWorking(m -> {
                if (m.getRecipeLogic().getLastRecipe() != null && m.getRecipeLogic().getLastRecipe().data.getBoolean("isCustom")) {
                    m.getRecipeLogic().markLastRecipeDirty();
                    ((IEnhancedRecipeLogic) m.getRecipeLogic()).gTECore$setLockRecipe(false);
                }
            })
            .register();

    MultiblockMachineDefinition MASS_FABRICATOR = multiblock("mass_fabricator", "质量发生器", ElectricMultiblockMachine::new)
            .allRotation()
            .recipe(GTERecipeTypes.MASS_FABRICATOR_RECIPES)
            .parallelizableTooltips()
            .customTooltipsBuilder(true, false, false)
            .parallelizablePerfectOverclock()
            .block(GTBlocks.MACHINE_CASING_UHV)
            .pattern((definition) -> FactoryBlockPattern.start()
                    .aisle("bbbbb", " c c ", " c c ", " c c ", "bbbbb")
                    .aisle("bbbbb", "cdfdc", "cdfdc", "cdfdc", "bbbbb")
                    .aisle("bbbbb", " e e ", " e e ", " e e ", "bfffb")
                    .aisle("bbbbb", " e e ", " e e ", " e e ", "bfffb")
                    .aisle("bbbbb", " e e ", " e e ", " e e ", "bfffb")
                    .aisle("bbbbb", " e e ", " e e ", " e e ", "bfffb")
                    .aisle("bbbbb", "cdfdc", "cdfdc", "cdfdc", "bbbbb")
                    .aisle("bbabb", " c c ", " c c ", " c c ", "bbbbb")
                    .where('a', controller(blocks(definition.get())))
                    .where('b', blocks(GTBlocks.MACHINE_CASING_UHV.get())
                            .or(abilities(IMPORT_ITEMS).setMaxGlobalLimited(1).setPreviewCount(1))
                            .or(abilities(IMPORT_FLUIDS).setMaxGlobalLimited(1).setPreviewCount(1))
                            .or(abilities(EXPORT_FLUIDS).setMaxGlobalLimited(1).setPreviewCount(1))
                            .or(abilities(INPUT_ENERGY).setMaxGlobalLimited(16).setPreviewCount(16))
                            .or(abilities(PARALLEL_HATCH).setMaxGlobalLimited(1))
                            .or(abilities(MAINTENANCE).setExactLimit(1)))
                    .where('c', blocks(GTBlocks.CASING_POLYTETRAFLUOROETHYLENE_PIPE.get()))
                    .where('d', blocks(GTEBlocks.HYPER_CORE.get()))
                    .where('e', blocks(GTBlocks.HERMETIC_CASING_UHV.get()))
                    .where('f', blocks(GCYMBlocks.HEAT_VENT.get()))
                    .build())
            .workableCasingRenderer(GTCEu.id("block/casings/voltage/uhv/side"), GTCEu.id("block/multiblock/gcym/large_electrolyzer"))
            .register();

    MultiblockMachineDefinition ADVANCED_MASS_FABRICATOR = multiblock("advanced_mass_fabricator", "进阶质量发生器", ElectricMultiblockMachine::new)
            .allRotation()
            .recipe(GTERecipeTypes.MASS_FABRICATOR_RECIPES)
            .eutMultiplierTooltips(0.8)
            .durationMultiplierTooltips(0.5)
            .parallelizableTooltips()
            .customTooltipsBuilder(true, true, false)
            .recipeModifiers(GTERecipeModifiers.HATCH_PARALLEL, GTERecipeModifiers.overclocking(true, 0.8, 0.5))
            .block(GTBlocks.MACHINE_CASING_UXV)
            .pattern((definition) -> FactoryBlockPattern.start(RelativeDirection.BACK, RelativeDirection.UP, RelativeDirection.LEFT)
                    .aisle("AAAAAAAAAA AAAAAAAAAA", "AAFFFFFFAA AAFFFFFFAA", "AAAAAAAAAA AAAAAAAAAA", "AAAAAAAAAA AAAAAAAAAA", "AAFFFFFFAA AAFFFFFFAA", "AAAAAAAAAA AAAAAAAAAA", "                     ", "AAAAAAAAAA AAAAAAAAAA", "AAFFFFFFAA AAFFFFFFAA", "AAAAAAAAAA AAAAAAAAAA", "AAAAAAAAAA AAAAAAAAAA", "AAFFFFFFAA AAFFFFFFAA", "AAAAAAAAAA AAAAAAAAAA")
                    .aisle("AAAAAAAAAA AAAAAAAAAA", "BDDDDDDDDDDDDDDDDDDDB", "BDDDDDDDD   DDDDDDDDB", "BDDDDDDDD   DDDDDDDDB", "BDDDDDDDDDDDDDDDDDDDB", "CDDDDDDDDA ADDDDDDDDC", " DDDDDDDD   DDDDDDDD ", "CDDDDDDDDA ADDDDDDDDC", "BDDDDDDDDDDDDDDDDDDDB", "BDDDDDDDD   DDDDDDDDB", "BDDDDDDDD   DDDDDDDDB", "BDDDDDDDDDDDDDDDDDDDB", "AAAAAAAAAA AAAAAAAAAA")
                    .aisle("AAAAAAAAAA AAAAAAAAAA", "BDDDDDDDD   DDDDDDDDB", "B                   B", "B                   B", "BDDDDDDDD   DDDDDDDDB", "C        A A        C", " EEEEEEEEEEEEEEEEEEE ", "C        A A        C", "BDDDDDDDD   DDDDDDDDB", "B                   B", "B                   B", "BDDDDDDDD   DDDDDDDDB", "AAAAAAAAAA AAAAAAAAAA")
                    .aisle("AAAAAAAAAA AAAAAAAAAA", "BDDDDDDDD   DDDDDDDDB", "B                   B", "B                   B", "BDDDDDDDD   DDDDDDDDB", "C        A A        C", " EEEEEEEEEEEEEEEEEEE ", "C        A A        C", "BDDDDDDDD   DDDDDDDDB", "B                   B", "B                   B", "BDDDDDDDD   DDDDDDDDB", "AAAAAAAAAA AAAAAAAAAA")
                    .aisle("AAAAAAAAAA AAAAAAAAAA", "BDDDDDDDDDDDDDDDDDDDB", "BDDDDDDDD   DDDDDDDDB", "BDDDDDDDD   DDDDDDDDB", "BDDDDDDDDDDDDDDDDDDDB", "CDDDDDDDDA ADDDDDDDDC", " DDDDDDDD   DDDDDDDD ", "CDDDDDDDDA ADDDDDDDDC", "BDDDDDDDDDDDDDDDDDDDB", "BDDDDDDDD   DDDDDDDDB", "BDDDDDDDD   DDDDDDDDB", "BDDDDDDDDDDDDDDDDDDDB", "AAAAAAAAAA AAAAAAAAAA")
                    .aisle("AAAAAAAAAA AAAAAAAAAA", "CDDDDDDDDA ADDDDDDDDC", "C        A A        C", "C        A A        C", "CDDDDDDDDA ADDDDDDDDC", "CAAAAAAAAA AAAAAAAAAC", "C                    ", "CAAAAAAAAA AAAAAAAAAC", "CDDDDDDDDA ADDDDDDDDC", "C        A A        C", "C        A A        C", "CDDDDDDDDA ADDDDDDDDC", "AAAAAAAAAA AAAAAAAAAA")
                    .aisle("                     ", " DDDDDDDD   DDDDDDDD ", " EEEEEEEEEEEEEEEEEEE ", " EEEEEEEEEEEEEEEEEEE ", " DDDDDDDD   DDDDDDDD ", "C                    ", "G                    ", "C                    ", " DDDDDDDD   DDDDDDDD ", " EEEEEEEEEEEEEEEEEEE ", " EEEEEEEEEEEEEEEEEEE ", " DDDDDDDD   DDDDDDDD ", "                     ")
                    .aisle("AAAAAAAAAA AAAAAAAAAA", "CDDDDDDDDA ADDDDDDDDC", "C        A A        C", "C        A A        C", "CDDDDDDDDA ADDDDDDDDC", "CAAAAAAAAA AAAAAAAAAC", "C                    ", "CAAAAAAAAA AAAAAAAAAC", "CDDDDDDDDA ADDDDDDDDC", "C        A A        C", "C        A A        C", "CDDDDDDDDA ADDDDDDDDC", "AAAAAAAAAA AAAAAAAAAA")
                    .aisle("AAAAAAAAAA AAAAAAAAAA", "BDDDDDDDDDDDDDDDDDDDB", "BDDDDDDDD   DDDDDDDDB", "BDDDDDDDD   DDDDDDDDB", "BDDDDDDDDDDDDDDDDDDDB", "CDDDDDDDDA ADDDDDDDDC", " DDDDDDDD   DDDDDDDD ", "CDDDDDDDDA ADDDDDDDDC", "BDDDDDDDDDDDDDDDDDDDB", "BDDDDDDDD   DDDDDDDDB", "BDDDDDDDD   DDDDDDDDB", "BDDDDDDDDDDDDDDDDDDDB", "AAAAAAAAAA AAAAAAAAAA")
                    .aisle("AAAAAAAAAA AAAAAAAAAA", "BDDDDDDDD   DDDDDDDDB", "B                   B", "B                   B", "BDDDDDDDD   DDDDDDDDB", "C        A A        C", " EEEEEEEEEEEEEEEEEEE ", "C        A A        C", "BDDDDDDDD   DDDDDDDDB", "B                   B", "B                   B", "BDDDDDDDD   DDDDDDDDB", "AAAAAAAAAA AAAAAAAAAA")
                    .aisle("AAAAAAAAAA AAAAAAAAAA", "BDDDDDDDD   DDDDDDDDB", "B                   B", "B                   B", "BDDDDDDDD   DDDDDDDDB", "C        A A        C", " EEEEEEEEEEEEEEEEEEE ", "C        A A        C", "BDDDDDDDD   DDDDDDDDB", "B                   B", "B                   B", "BDDDDDDDD   DDDDDDDDB", "AAAAAAAAAA AAAAAAAAAA")
                    .aisle("AAAAAAAAAA AAAAAAAAAA", "BDDDDDDDDDDDDDDDDDDDB", "BDDDDDDDD   DDDDDDDDB", "BDDDDDDDD   DDDDDDDDB", "BDDDDDDDDDDDDDDDDDDDB", "CDDDDDDDDA ADDDDDDDDC", " DDDDDDDD   DDDDDDDD ", "CDDDDDDDDA ADDDDDDDDC", "BDDDDDDDDDDDDDDDDDDDB", "BDDDDDDDD   DDDDDDDDB", "BDDDDDDDD   DDDDDDDDB", "BDDDDDDDDDDDDDDDDDDDB", "AAAAAAAAAA AAAAAAAAAA")
                    .aisle("AAAAAAAAAA AAAAAAAAAA", "AAFFFFFFAA AAFFFFFFAA", "AAAAAAAAAA AAAAAAAAAA", "AAAAAAAAAA AAAAAAAAAA", "AAFFFFFFAA AAFFFFFFAA", "AAAAAAAAAA AAAAAAAAAA", "                     ", "AAAAAAAAAA AAAAAAAAAA", "AAFFFFFFAA AAFFFFFFAA", "AAAAAAAAAA AAAAAAAAAA", "AAAAAAAAAA AAAAAAAAAA", "AAFFFFFFAA AAFFFFFFAA", "AAAAAAAAAA AAAAAAAAAA")
                    .where('A', blocks(GTBlocks.MACHINE_CASING_UXV.get()))
                    .where('B', blocks(GTEBlocks.RHENIUM_REINFORCED_ENERGY_GLASS.get()))
                    .where('C', blocks(GTBlocks.MACHINE_CASING_UXV.get())
                            .or(GTEPredicates.autoLaserAbilities(definition.getRecipeTypes()))
                            .or(abilities(MAINTENANCE).setExactLimit(1)))
                    .where('D', blocks(GTEBlocks.TITANSTEEL_COIL_BLOCK.get()))
                    .where('E', blocks(GTEBlocks.HOLLOW_CASING.get()))
                    .where('F', blocks(GTEBlocks.RESTRAINT_DEVICE.get()))
                    .where('G', controller(blocks(definition.get())))
                    .where(' ', any())
                    .build())
            .workableCasingRenderer(GTCEu.id("block/casings/voltage/uxv/side"), GTCEu.id("block/multiblock/fusion_reactor"))
            .register();

    MultiblockMachineDefinition PRECISION_ASSEMBLER = multiblock("precision_assembler", "精密组装机", TierCasingParallelMultiblockMachine.createParallel(m -> 1 << (m.getCasingTier(GLASS_TIER)), true, GLASS_TIER, MACHINE_CASING_TIER))
            .allRotation()
            .recipe(GTERecipeTypes.PRECISION_ASSEMBLER_RECIPES)
            .recipe(GTRecipeTypes.ASSEMBLER_RECIPES)
            .tooltipsText("The machine casing tier determines the upper limit of recipe tier, while the glass tier determines the parallel.", "外壳等级决定配方等级上限，玻璃等级决定并行")
            .customTooltipsBuilder(true, false, false)
            .perfectOverclock()
            .block(GTEBlocks.OXIDATION_RESISTANT_HASTELLOY_N_MECHANICAL_CASING)
            .pattern(definition -> FactoryBlockPattern.start()
                    .aisle("bbbbbbbbb", "d       d", "d       d", "d       d", "bbbbbbbbb")
                    .aisle("bAAAAAAAb", "bcccccccb", "bcccccccb", "bcccccccb", "bbbbbbbbb")
                    .aisle("bAAAAAAAb", "b-------b", "b-------b", "b-------b", "bbbbbbbbb")
                    .aisle("bAAAAAAAb", "bcccccccb", "bcccccccb", "bcccccccb", "bbbbbbbbb")
                    .aisle("bbbbabbbb", "d       d", "d       d", "d       d", "bbbbbbbbb")
                    .where('a', controller(blocks(definition.get())))
                    .where('b', blocks(GTEBlocks.OXIDATION_RESISTANT_HASTELLOY_N_MECHANICAL_CASING.get())
                            .setMinGlobalLimited(70)
                            .or(autoAbilities(definition.getRecipeTypes()))
                            .or(abilities(MAINTENANCE).setExactLimit(1)))
                    .where('c', GTEPredicates.glass())
                    .where('d', blocks(ChemicalHelper.getBlock(TagPrefix.frameGt, GTEMaterials.HastelloyN)))
                    .where('A', GTEPredicates.machineCasing())
                    .where('-', air())
                    .where(' ', any())
                    .build())
            .workableCasingRenderer(GTECore.id("block/casings/oxidation_resistant_hastelloy_n_mechanical_casing"), GTCEu.id("block/multiblock/gcym/large_assembler"))
            .register();

    MultiblockMachineDefinition FISHING_GROUND = multiblock("fishing_ground", "渔场", FishingGroundMachine::new)
            .nonYAxisRotation()
            .recipe(GTERecipeTypes.FISHING_GROUND_RECIPES)
            .parallelizableTooltips()
            .parallelizableOverclock()
            .block(GTEBlocks.ALUMINIUM_BRONZE_CASING)
            .pattern(definition -> FactoryBlockPattern.start(RelativeDirection.RIGHT, RelativeDirection.UP, RelativeDirection.BACK)
                    .aisle("    AAAAA    ", "    AAFAA    ", "    BBBBB    ", "             ")
                    .aisle("   BBBBBBB   ", "   BCCCCCB   ", "   BB E BB   ", "             ")
                    .aisle("  BBBBBBBBB  ", "  BCCCCCCCB  ", "  BB  E  BB  ", "             ")
                    .aisle(" BBBBBBBBBBB ", " BCCCCCCCCCB ", " BB   E   BB ", "             ")
                    .aisle("ABBBBBBBBBBBA", "ACCCCCCCCCCCA", "BB    E    BB", "             ")
                    .aisle("ABBBBBBBBBBBA", "ACCCCBEBCCCCA", "B    BEB    B", "     BBB     ")
                    .aisle("ABBBBBBBBBBBA", "ACCCCEDECCCCA", "BEEEEEDEEEEEB", "     BBB     ")
                    .aisle("ABBBBBBBBBBBA", "ACCCCBEBCCCCA", "B    BDB    B", "     BBB     ")
                    .aisle("ABBBBBBBBBBBA", "ACCCCCCCCCCCA", "BB    D    BB", "             ")
                    .aisle(" BBBBBBBBBBB ", " BCCCCCCCCCB ", " BB   D   BB ", "             ")
                    .aisle("  BBBBBBBBB  ", "  BCCCCCCCB  ", "  BB  D  BB  ", "             ")
                    .aisle("   BBBBBBB   ", "   BCCCCCB   ", "   BB D BB   ", "             ")
                    .aisle("    AAAAA    ", "    AAAAA    ", "    BBBBB    ", "             ")
                    .where('A', blocks(GTEBlocks.ALUMINIUM_BRONZE_CASING.get())
                            .or(autoAbilities(definition.getRecipeTypes()))
                            .or(abilities(PARALLEL_HATCH).setMaxGlobalLimited(1))
                            .or(abilities(MAINTENANCE).setExactLimit(1)))
                    .where('B', blocks(GTEBlocks.ALUMINIUM_BRONZE_CASING.get()))
                    .where('C', fluids(Fluids.WATER))
                    .where('D', blocks(GTBlocks.CASING_STEEL_PIPE.get()))
                    .where('E', blocks(ChemicalHelper.getBlock(TagPrefix.frameGt, GTMaterials.StainlessSteel)))
                    .where('F', controller(blocks(definition.get())))
                    .where(' ', any())
                    .build())
            .workableCasingRenderer(GTECore.id("block/casings/aluminium_bronze_casing"), GTCEu.id("block/multiblock/gcym/large_assembler"))
            .register();

    MultiblockMachineDefinition LAVA_FURNACE = multiblock("lava_furnace", "熔岩炉", ElectricMultiblockMachine::new)
            .allRotation()
            .recipe(GTERecipeTypes.LAVA_FURNACE_RECIPES)
            .tooltipsText("Each provided piece of any type of cobblestone or stone can output 1B of lava.", "每提供一个任意类型的圆石或石头可输出1B熔岩")
            .overclock()
            .block(GTBlocks.CASING_BRONZE_BRICKS)
            .pattern(definition -> FactoryBlockPattern.start()
                    .aisle("CCC", "DDD", "DDD")
                    .aisle("CCC", "D D", "DMD")
                    .aisle("CCC", "DAD", "DDD")
                    .where('A', controller(blocks(definition.get())))
                    .where('D', blocks(GTBlocks.CASING_BRONZE_BRICKS.get())
                            .or(autoAbilities(definition.getRecipeTypes())))
                    .where('M', abilities(MUFFLER))
                    .where('C', blocks(GTBlocks.FIREBOX_BRONZE.get()))
                    .where(' ', air())
                    .build())
            .workableCasingRenderer(GTCEu.id("block/casings/solid/machine_casing_bronze_plated_bricks"), GTCEu.id("block/multiblock/steam_oven"))
            .register();

    MultiblockMachineDefinition LARGE_GAS_COLLECTOR = multiblock("large_gas_collector", "大型集气室", CustomParallelMultiblockMachine.createParallel(m -> 100000, true))
            .noneRotation()
            .recipe(GTERecipeTypes.LARGE_GAS_COLLECTOR_RECIPES)
            .overclock()
            .block(GTBlocks.CASING_STEEL_SOLID)
            .pattern(definition -> FactoryBlockPattern.start()
                    .aisle("aaaaa", "abbba", "abbba", "abbba", "aaaaa")
                    .aisle("aaaaa", "bcccb", "bcccb", "bcccb", "abbba")
                    .aisle("aaaaa", "bcccb", "bcecb", "bcccb", "abdba")
                    .aisle("aaaaa", "bcccb", "bcccb", "bcccb", "abbba")
                    .aisle("aaaaa", "abbba", "abbba", "abbba", "aaaaa")
                    .where('d', controller(blocks(definition.get())))
                    .where('a', blocks(GTBlocks.CASING_STEEL_SOLID.get())
                            .setMinGlobalLimited(40)
                            .or(autoAbilities(definition.getRecipeTypes()))
                            .or(abilities(MAINTENANCE).setExactLimit(1)))
                    .where('c', blocks(GTBlocks.CASING_TUNGSTENSTEEL_PIPE.get()))
                    .where('b', blocks(GTBlocks.CASING_GRATE.get()))
                    .where('e', blocks(GTBlocks.HERMETIC_CASING_IV.get()))
                    .build())
            .workableCasingRenderer(GTCEu.id("block/casings/solid/machine_casing_solid_steel"), GTCEu.id("block/machines/gas_collector"))
            .register();

    MultiblockMachineDefinition ENGRAVING_LASER_PLANT = multiblock("engraving_laser_plant", "激光蚀刻工厂", ElectricMultiblockMachine::new)
            .allRotation()
            .recipe(GTERecipeTypes.PRECISION_LASER_ENGRAVER_RECIPES)
            .recipe(GTRecipeTypes.LASER_ENGRAVER_RECIPES)
            .recipe(GTERecipeTypes.LASER_WELDER_RECIPES)
            .tooltipsText("Precision laser mode does not support parallelism, Running the Laser Welder formula at speed x5.", "精密激光模式不支持并行，运行激光焊接配方时速度x5")
            .parallelizableTooltips()
            .customTooltipsBuilder(true, false, false)
            .recipeModifiers((machine, recipe) -> {
                if (machine instanceof ElectricMultiblockMachine workableElectricMultiblockMachine) {
                    if (workableElectricMultiblockMachine.getRecipeType() == GTRecipeTypes.LASER_ENGRAVER_RECIPES) return GTERecipeModifiers.hatchParallel(workableElectricMultiblockMachine, recipe);
                    if (workableElectricMultiblockMachine.getRecipeType() == GTERecipeTypes.LASER_WELDER_RECIPES) {
                        recipe.duration = recipe.duration / 5;
                        return GTERecipeModifiers.hatchParallel(workableElectricMultiblockMachine, recipe);
                    }
                }
                return recipe;
            }, GTERecipeModifiers.PERFECT_OVERCLOCKING)
            .block(GTEBlocks.IRIDIUM_CASING)
            .pattern(definition -> FactoryBlockPattern.start(RelativeDirection.RIGHT, RelativeDirection.UP, RelativeDirection.BACK)
                    .aisle("       aaaaaaa       ", "       aaaaaaa       ", "       aaa~aaa       ", "       aaaaaaa       ", "        aaaaa        ", "                     ", "                     ", "                     ", "                     ", "                     ", "                     ", "                     ")
                    .aisle("        AAAAA        ", "        JDIDJ        ", "        A   A        ", "         AAA         ", "          B          ", "                     ", "                     ", "                     ", "                     ", "                     ", "                     ", "                     ")
                    .aisle("        AAAAA        ", "        JDIDJ        ", "        A   A        ", "         AAA         ", "          B          ", "                     ", "                     ", "                     ", "                     ", "                     ", "                     ", "                     ")
                    .aisle("   AAA  AAAAA  AAA   ", "   FAF  JDIDJ  FAF   ", "   FAF  A   A  FAF   ", "   FAF   AAA   FAF   ", "   FAF    B    FAF   ", "   FAF         FAF   ", "   AAA         AAA   ", "                     ", "                     ", "                     ", "                     ", "                     ")
                    .aisle("  AAAAA AAAAA AAAAA  ", "  FMDMF JDIDJ FBDBF  ", "  FM MF A   A FB BF  ", "  FM MF  AAA  FB BF  ", "  FM MF   B   FB BF  ", "  FMDMF       FBDBF  ", "  ABBBA       ABBBA  ", "   AAA         AAA   ", "                     ", "                     ", "                     ", "                     ")
                    .aisle("  AAAAA AAAAA AAAAA  ", "  ADDDA JDIDJ ADDDA  ", "  A I A A   A A I A  ", "  A I A  AAA  A I A  ", "  A I A   B   A I A  ", "  ADDDA       ADDDA  ", "  ABBBA       ABBBA  ", "   AAA         AAA   ", "                     ", "                     ", "                     ", "                     ")
                    .aisle("  AAAAA AAAAA AAAAA  ", "  FMDMF JDIDJ FBDBF  ", "  FM MF A   A FB BF  ", "  FM MF  AAA  FB BF  ", "  FM MF   B   FB BF  ", "  FMDMF       FBDBF  ", "  ABBBA       ABBBA  ", "   AAA         AAA   ", "                     ", "                     ", "                     ", "                     ")
                    .aisle("   AAA  AAAAA  AAA   ", "   FAF  JDIDJ  FAF   ", "   FAF  A   A  FAF   ", "   FAF   AAA   FAF   ", "   FAF    B    FAF   ", "   FAF         FAF   ", "   AAA         AAA   ", "                     ", "                     ", "                     ", "                     ", "                     ")
                    .aisle("       AAAAAAA       ", "       JADIDAJ       ", "       AABBBAA       ", "    I   AAAAA   I    ", "         AAA         ", "         AAA         ", "                     ", "                     ", "                     ", "                     ", "                     ", "                     ")
                    .aisle(" AAA   AAAAAAA   AAA ", " AKA   JDBBBDJ   ALA ", " AKA   ABDDDBA   ALA ", " AKAI  AABBBAA  IALA ", " AKA    AAAAA    ALA ", " AAA    AAHAA    AAA ", "         AHA         ", "         AHA         ", "         AHA         ", "         AHA         ", "         AAA         ", "                     ")
                    .aisle("AAAAA AAAAAAAAA AAAAA", "ABBBA JDB   BDJ ABBBA", "ACDCA ABD I DBA ACDCA", "ACDCA  AB   BA  ACDCA", "ABBBA  AAAAAAA  ABBBA", "AHHHA  AAD DAA  ALLLA", " AAA    AD DA    AAA ", "        AD DA        ", "        AD DA        ", "        AAAAA        ", "        ABBBA        ", "         BBB         ")
                    .aisle("AAAAA AAAAAAAAA AAAAA", "ABBBA JDB I BDJ ABBBA", "AD DA ABDIIIDBA AD DA", "AD DAIIAB I BAIIAD DA", "ABBBA  AAAAAAA  ABBBA", "AHHHA  AH I HA  ALLLA", " AAACCCCH I HCCCCAAA ", "        H I H        ", "        H I H        ", "        HAAAH        ", "        ABBBA        ", "         BBB         ")
                    .aisle("AAAAA AAAAAAAAA AAAAA", "ABBBA JDB   BDJ ABBBA", "ACDCA ABD I DBA ACDCA", "ACDCA  AB   BA  ACDCA", "ABBBA  AAAAAAA  ABBBA", "AHHHA  AAD DAA  ALLLA", " AAA    AD DA    AAA ", "        AD DA        ", "        AD DA        ", "        AAAAA        ", "        ABBBA        ", "         BBB         ")
                    .aisle(" AAA   AAAAAAA   AAA ", " AKA   JDBBBDJ   ALA ", " AKA   ABDDDBA   ALA ", " AKAI  AABBBAA  IALA ", " AKA    AAAAA    ALA ", " AAA    AAHAA    AAA ", "         AHA         ", "         AHA         ", "         AHA         ", "         AHA         ", "         AAA         ", "                     ")
                    .aisle("       AAAAAAA       ", "       JJDDDJJ       ", "       AABBBAA       ", "    I   AAAAA   I    ", "         AAA         ", "         AAA         ", "          C          ", "                     ", "                     ", "                     ", "                     ", "                     ")
                    .aisle("   AAA   AAA   AAA   ", "   FAF   JJJ   FAF   ", "   FAF   AAA   FAF   ", "   FAF    I    FAF   ", "   FAF         FAF   ", "   FAF         FAF   ", "   AAA    C    AAA   ", "                     ", "                     ", "                     ", "                     ", "                     ")
                    .aisle("  AAAAA       AAAAA  ", "  FHDHF       FEDEF  ", "  FH HF       FE EF  ", "  FH HF   I   FE EF  ", "  FH HF       FE EF  ", "  FHDHF       FEDEF  ", "  ABBBA   C   ABBBA  ", "   AAA         AAA   ", "                     ", "                     ", "                     ", "                     ")
                    .aisle("  AAAAA  AAA  AAAAA  ", "  ADDDA  AAA  ADDDA  ", "  A I A  AAA  A I A  ", "  A I AIIAAAIIA I A  ", "  A I A  AAA  A I A  ", "  ADDDA  AAA  ADDDA  ", "  ABBBA   C   ABBBA  ", "   AAA         AAA   ", "                     ", "                     ", "                     ", "                     ")
                    .aisle("  AAAAA AAAAA AAAAA  ", "  FHDHF ABBBA FEDEF  ", "  FH HF ACDCA FE EF  ", "  FH HF ACDCA FE EF  ", "  FH HF ABBBA FE EF  ", "  FHDHF AEEEA FEDEF  ", "  ABBBA  AAA  ABBBA  ", "   AAA         AAA   ", "                     ", "                     ", "                     ", "                     ")
                    .aisle("   AAA  AAAAA  AAA   ", "   FAF  GBBBG  FAF   ", "   FAF  GD DG  FAF   ", "   FAF  GD DG  FAF   ", "   FAF  GBBBG  FAF   ", "   FAF  AEEEA  FAF   ", "   AAA   AAA   AAA   ", "                     ", "                     ", "                     ", "                     ", "                     ")
                    .aisle("        AAAAA        ", "        ABBBA        ", "        ACDCA        ", "        ACDCA        ", "        ABBBA        ", "        AEEEA        ", "         AAA         ", "                     ", "                     ", "                     ", "                     ", "                     ")
                    .aisle("         AAA         ", "         AAA         ", "         AAA         ", "         AAA         ", "         AAA         ", "         AAA         ", "                     ", "                     ", "                     ", "                     ", "                     ", "                     ")
                    .where('~', controller(blocks(definition.get())))
                    .where('A', blocks(GTEBlocks.IRIDIUM_CASING.get()))
                    .where('B', blocks(GTBlocks.HIGH_POWER_CASING.get()))
                    .where('C', blocks(ChemicalHelper.getBlock(TagPrefix.frameGt, GTMaterials.Neutronium)))
                    .where('D', blocks(GTEBlocks.AMPROSIUM_GEARBOX.get()))
                    .where('E', blocks(GTEBlocks.COMPONENT_ASSEMBLY_LINE_CASING_UV.get()))
                    .where('F', blocks(GTBlocks.FUSION_GLASS.get()))
                    .where('G', blocks(GCYMBlocks.HEAT_VENT.get()))
                    .where('H', blocks(GTBlocks.HERMETIC_CASING_UHV.get()))
                    .where('I', blocks(GTEBlocks.AMPROSIUM_PIPE_CASING.get()))
                    .where('J', blocks(GTBlocks.FILTER_CASING_STERILE.get()))
                    .where('K', blocks(GTEBlocks.ADVANCED_COMPRESSED_FUSION_COIL.get()))
                    .where('L', blocks(GCYMBlocks.ELECTROLYTIC_CELL.get()))
                    .where('M', blocks(GTEBlocks.MOLECULAR_CASING.get()))
                    .where('a', blocks(GTEBlocks.IRIDIUM_CASING.get())
                            .or(abilities(PARALLEL_HATCH).setMaxGlobalLimited(1))
                            .or(abilities(IMPORT_ITEMS).setPreviewCount(1))
                            .or(abilities(IMPORT_FLUIDS).setPreviewCount(1))
                            .or(abilities(INPUT_ENERGY).setMaxGlobalLimited(2).setPreviewCount(1))
                            .or(abilities(MAINTENANCE).setExactLimit(1))
                            .or(abilities(EXPORT_ITEMS).setPreviewCount(1))
                            .or(abilities(COMPUTATION_DATA_RECEPTION).setExactLimit(1)))
                    .where(' ', any())
                    .build())
            .workableCasingRenderer(GTECore.id("block/casings/iridium_casing"), GTCEu.id("block/multiblock/gcym/large_engraving_laser"))
            .register();

    MultiblockMachineDefinition MEGA_ALLOY_BLAST_SMELTER = multiblock("mega_alloy_blast_smelter", "巨型合金冶炼炉", CoilMultiblockMachine.createCoilMachine(true, true))
            .nonYAxisRotation()
            .recipe(GCYMRecipeTypes.ALLOY_BLAST_RECIPES)
            .eutMultiplierTooltips(0.8)
            .durationMultiplierTooltips(0.6)
            .tooltipsKey("gtceu.machine.electric_blast_furnace.tooltip.2")
            .parallelizableTooltips()
            .recipeModifier(GTERecipeModifiers.GCYM_OVERCLOCKING)
            .block(GCYMBlocks.CASING_HIGH_TEMPERATURE_SMELTING)
            .pattern(definition -> FactoryBlockPattern.start()
                    .aisle("   eeeee   ", "   cbbbc   ", "   cbbbc   ", "   cbbbc   ", "   eeeee   ", "   bbbbb   ", "           ", "           ", "           ", "           ", "           ", "           ", "           ", "           ", "           ", "           ", "           ", "           ")
                    .aisle("  ebbbbbe  ", "  c     c  ", "  c     c  ", "  c     c  ", "  efffffe  ", "  bbbbbbb  ", "   bbbbb   ", "   ccccc   ", "   ccccc   ", "   ccccc   ", "   ccccc   ", "   ccccc   ", "   ccccc   ", "   ccccc   ", "   ccccc   ", "   ccccc   ", "   bbbbb   ", "           ")
                    .aisle(" ebbbbbbbe ", " cbeeeeebc ", " cbeeeeebc ", " cbeeeeebc ", " ebeeeeebe ", " bbbbbbbbb ", "  baaaaab  ", "  caaaaac  ", "  caaaaac  ", "  caaaaac  ", "  caaaaac  ", "  caaaaac  ", "  caaaaac  ", "  caaaaac  ", "  caaaaac  ", "  caaaaac  ", "  bbbbbbb  ", "   bbbbb   ")
                    .aisle("ebbbbbbbbbe", "c ehhhhhe c", "c eiiiiie c", "c ejjjjje c", "efeeeeeeefe", "bbbb   bbbb", " baa   aab ", " caa   aac ", " caa   aac ", " caa   aac ", " caa   aac ", " caa   aac ", " caa   aac ", " caa   aac ", " caa   aac ", " caa   aac ", " bbb   bbb ", "  bbbbbbb  ")
                    .aisle("ebbbbbbbbbe", "b ehhhhhe b", "b eiiiiie b", "b ejjjjje b", "efeeeeeeefe", "bbb     bbb", " ba     ab ", " ca     ac ", " ca     ac ", " ca     ac ", " ca     ac ", " ca     ac ", " ca     ac ", " ca     ac ", " ca     ac ", " ca     ac ", " bb     bb ", "  bbbbbbb  ")
                    .aisle("ebbbbbbbbbe", "b ehhkhhe b", "b eiikiie b", "b ejjkjje b", "efeeekeeefe", "bbb  k  bbb", " ba  k  ab ", " ca  k  ac ", " ca  k  ac ", " ca  k  ac ", " ca  k  ac ", " ca  k  ac ", " ca  k  ac ", " ca  k  ac ", " ca  k  ac ", " ca  k  ac ", " bb  k  bb ", "  bbbgbbb  ")
                    .aisle("ebbbbbbbbbe", "b ehhhhhe b", "b eiiiiie b", "b ejjjjje b", "efeeeeeeefe", "bbb     bbb", " ba     ab ", " ca     ac ", " ca     ac ", " ca     ac ", " ca     ac ", " ca     ac ", " ca     ac ", " ca     ac ", " ca     ac ", " ca     ac ", " bb     bb ", "  bbbbbbb  ")
                    .aisle("ebbbbbbbbbe", "c ehhhhhe c", "c eiiiiie c", "c ejjjjje c", "efeeeeeeefe", "bbbb   bbbb", " baa   aab ", " caa   aac ", " caa   aac ", " caa   aac ", " caa   aac ", " caa   aac ", " caa   aac ", " caa   aac ", " caa   aac ", " caa   aac ", " bbb   bbb ", "  bbbbbbb  ")
                    .aisle(" ebbbbbbbe ", " cbeeeeebc ", " cbeeeeebc ", " cbeeeeebc ", " ebeeeeebe ", " bbbbbbbbb ", "  baaaaab  ", "  caaaaac  ", "  caaaaac  ", "  caaaaac  ", "  caaaaac  ", "  caaaaac  ", "  caaaaac  ", "  caaaaac  ", "  caaaaac  ", "  caaaaac  ", "  bbbbbbb  ", "   bbbbb   ")
                    .aisle("  ebbbbbe  ", "  c     c  ", "  c     c  ", "  c     c  ", "  efffffe  ", "  bbbbbbb  ", "   bbbbb   ", "   ccccc   ", "   ccccc   ", "   ccccc   ", "   ccccc   ", "   ccccc   ", "   ccccc   ", "   ccccc   ", "   ccccc   ", "   ccccc   ", "   bbbbb   ", "           ")
                    .aisle("   eeeee   ", "   cbbbc   ", "   cb~bc   ", "   cbbbc   ", "   eeeee   ", "   bbbbb   ", "           ", "           ", "           ", "           ", "           ", "           ", "           ", "           ", "           ", "           ", "           ", "           ")
                    .where('~', controller(blocks(definition.get())))
                    .where('b', blocks(GCYMBlocks.CASING_HIGH_TEMPERATURE_SMELTING.get()).setMinGlobalLimited(280)
                            .or(GTEPredicates.autoMnaAccelerateAbilities(definition.getRecipeTypes()))
                            .or(abilities(MAINTENANCE).setExactLimit(1))
                            .or(abilities(PARALLEL_HATCH).setMaxGlobalLimited(1)))
                    .where('a', heatingCoils())
                    .where('g', abilities(MUFFLER))
                    .where('e', blocks(GCYMBlocks.HEAT_VENT.get()))
                    .where('c', blocks(GTBlocks.CASING_TEMPERED_GLASS.get()))
                    .where('f', blocks(GTBlocks.CASING_EXTREME_ENGINE_INTAKE.get()))
                    .where('h', blocks(GTBlocks.FIREBOX_STEEL.get()))
                    .where('i', blocks(GTBlocks.FIREBOX_TITANIUM.get()))
                    .where('j', blocks(GTBlocks.FIREBOX_TUNGSTENSTEEL.get()))
                    .where('k', blocks(GTBlocks.CASING_TUNGSTENSTEEL_PIPE.get()))
                    .where(' ', any())
                    .build())
            .workableCasingRenderer(GTCEu.id("block/casings/gcym/high_temperature_smelting_casing"), GTCEu.id("block/multiblock/gcym/blast_alloy_smelter"))
            .register();

    MultiblockMachineDefinition MAGNETIC_CONFINEMENT_DIMENSIONALITY_SHOCK_DEVICE = multiblock("magnetic_confinement_dimensionality_shock_device", "磁约束维度震荡装置", ElectricMultiblockMachine::new)
            .allRotation()
            .recipe(GTERecipeTypes.DIMENSIONALLY_TRANSCENDENT_MIXER_RECIPES)
            .recipe(GTRecipeTypes.MIXER_RECIPES)
            .tooltipsText("Time multiplication factor for running the mixer recipe is 0.1", "运行搅拌机配方时耗时倍数为0.1")
            .parallelizableTooltips()
            .customTooltipsBuilder(true, true, false)
            .recipeModifiers((machine, recipe) -> {
